Workbook

Sheet 안내
A1: 실측 참가자 섭외 케이스 · 자세별 합격 기준 (64ch)
A2: SeatCare 64채널(방석 32 + 등받이 32) 실측용. 작성 2026-10-18, 근거 데이터: feat/yewon 커밋 27c67e4 (4명 28파일).
A4: 이 파일로 할 수 있는 것
A5: 1 | B5: 섭외: '섭외 케이스'에서 누구를 더 모아야 하는지 보고, '참가자 명단'에 사람을 적으면 키·체중으로 케이스가 자동 배정됩니다.
A6: 2 | B6: 수집: '합격 기준'의 자세 요령대로 8자세를 수집합니다(자세당 20초).
A7: 3 | B7: 점검: 수집한 폴더에 qc_64ch.py를 돌려 나온 CSV를 '수집 현황' A6부터 붙여 넣으면 파일마다 PASS/FAIL이 나옵니다.
A8: 4 | B8: 확인: '자세 수집 현황'에서 사람 × 자세별 부족한 칸을 보고, 불합격 파일은 파일명에 _reject를 붙여 재촬영합니다.
A9: 5 | B9: 조정: 사람이 늘면 '실측 관찰값'을 보며 '합격 기준 수치표'의 숫자를 고칩니다. 판정과 설명이 함께 바뀝니다.
A11: 자세 8종 (앱 순서 0~7)
A12: 값 | B12: 코드 | C12: 영문 | D12: 한글 | E12: 등받이 핵심 신호 | F12: 방석 핵심 신호
A13: 0 | B13: p0 | C13: not_sitting | D13: 앉지 않음 | E13: 전부 0 | F13: 전부 0
A14: 1 | B14: p1 | C14: sitting_straight | D14: 정자세 | E14: 허리·중간 줄 접촉 | F14: 좌우 균형(40~60%)
A15: 2 | B15: p2 | C15: lean_forward | D15: 앞으로 숙이기 | E15: 전부 0 (등이 안 닿음) | F15: 엉덩이 비중 감소(32% 이하)
A16: 3 | B16: p3 | C16: cross_leg_right | D16: 오른다리 꼬기 | E16: 접촉 유지 | F16: 오른쪽 비율 낮아짐(46% 이하)
A17: 4 | B17: p4 | C17: cross_leg_left | D17: 왼다리 꼬기 | E17: 접촉 유지 | F17: 오른쪽 비율 높아짐(60% 이상)
A18: 5 | B18: p5 | C18: lean_right | D18: 오른쪽 기대기 | E18: 오른쪽 비율 80% 이상 | F18: 오른쪽 비율 52% 이상
A19: 6 | B19: p6 | C19: lean_left | D19: 왼쪽 기대기 | E19: 오른쪽 비율 20% 이하 | F19: 뚜렷한 신호 없음
A20: 7 | B20: p7 | C20: turtle_neck | D20: 거북목 | E20: 등은 닿고 어깨 줄 거의 0 | F20: 정자세와 비슷(40~60%)
A22: 좌표계 (2026-10-18, 방석·등받이 모두 뒤집은 뒤 기준)
A23: • | B23: 방석 ch0~31: 번호가 작을수록 사용자의 왼쪽. 엉덩이 ch0~9, 허벅지 ch10~23, 무릎 ch24~31 (위아래는 그대로).
A24: • | B24: 등받이 ch32~63: 번호가 작을수록 사용자의 오른쪽. 허리 ch32~41, 중간 ch42~55, 어깨 ch56~63.
A25: • | B25: 뒤집기 전에 모은 32ch 데이터는 좌우가 반대입니다. 이 파일의 기준과 qc_64ch.py는 뒤집은 뒤 데이터에만 쓰세요.
A27: 시트 구성
B28: 섭외 케이스 | C28: 기본 18(성별×키×체형) + 확장 17. 우선순위·목표·확보·부족
B29: 참가자 명단 | C29: 사람 입력 → BMI·케이스·합격 현황 자동
B30: 분류 기준 | C30: 케이스 구간 경계값(키·BMI)
B31: 합격 기준 | C31: 자세별 요령·기대 패턴·수치 기준·실패 조치, 공통 품질, 참가자 단위 기준
B32: 합격 기준 수치표 | C32: 판정에 쓰이는 숫자(하한/상한). 여기만 고치면 전체가 바뀜
B33: 수집 현황 | C33: 파일별 지표와 자동 판정(PASS/FAIL)
B34: 자세 수집 현황 | C34: 사람 × 자세 합격 파일 수, 부족 표시
B35: 실측 관찰값 | C35: 자세 × 지표의 최소·평균·최대와 현재 기준
A37: 색 규칙
B38: 노란 칸 + 파란 글씨 | C38: 직접 입력하는 칸 (키·체중, 목표 인원, 기준값 등)
B39: 파란 글씨 | C39: 실측에서 가져온 고정 입력값 / 직접 바꿀 수 있는 기준 숫자
B40: 초록 글씨 | C40: 다른 시트를 참조하는 수식
B41: 검정 글씨 | C41: 같은 시트 안에서 계산되는 수식 / 설명 문구
A43: 알아 둘 한계
A44: • | B44: 수치 기준은 4명 28파일(자세당 2~4개)에서 정한 초안입니다. 사람이 늘면 바뀔 수 있습니다.
A45: • | B45: 방석 좌우는 '방석도 뒤집었다'는 팀 확인에 따랐습니다. 등받이처럼 데이터로 경계를 확정한 것은 아니므로 탭 테스트로 확인하세요. 방석 좌우가 반대라면 방석 오른쪽 비율 기준(40~60, 46 이하, 60 이상, 52 이상)을 100에서 뺀 값으로 바꿔야 합니다.
A46: • | B46: 왼쪽 기대기는 방석에 뚜렷한 쏠림이 없어서(관찰 44~55%) 등받이로만 판정합니다.
...

Sheet 섭외 케이스
A1: 실측 참가자 섭외 케이스 (64ch: 방석 + 등받이)
A2: 기본 18케이스(성별 × 키 × 체형) + 확장 17케이스. 우선순위 1만 모아도 6명(남녀 포함)이 됩니다. 확보 인원은 '참가자 명단'에서 자동 집계됩니다.
A4: 케이스 ID | B4: 구분 | C4: 성별 | D4: 키 | E4: 체형 / 조건 | F4: 검증 목적 (방석·등받이에서 무엇을 보려는가) | G4: 우선순위 | H4: 목표 인원 | I4: 확보 인원 | J4: 부족 | K4: 비고
A5: F1 | B5: 기본 | C5: 여 | D5: ='분류 기준'!$C$5&"cm 미만" -> 158cm 미만 | E5: ="BMI "&'분류 기준'!$C$9&" 미만" -> BMI 18.5 미만 | F5: 앉은키가 작아 등받이 어깨 줄이 닿는 위치가 달라질 수 있음 → 거북목·정자세의 어깨 줄 값 확인; 압력이 약해 앉지 않음·앞으로 숙이기와 구분되는지, 반응 채널 수 확인 | G5: 1 | H5: 1 | I5: =COUNTIF('참가자 명단'!$H$6:$H$55,$A5)+COUNTIF('참가자 명단'!$I$6:$I$55,$A5) -> 0 | J5: =MAX(0,H5-I5) -> 1
A6: F2 | B6: 기본 | C6: 여 | D6: ='분류 기준'!$C$5&"cm 미만" -> 158cm 미만 | E6: ="BMI "&'분류 기준'!$C$9&"~"&'분류 기준'!$C$10&" 미만" -> BMI 18.5~23 미만 | F6: 앉은키가 작아 등받이 어깨 줄이 닿는 위치가 달라질 수 있음 → 거북목·정자세의 어깨 줄 값 확인 | G6: 2 | H6: 1 | I6: =COUNTIF('참가자 명단'!$H$6:$H$55,$A6)+COUNTIF('참가자 명단'!$I$6:$I$55,$A6) -> 0 | J6: =MAX(0,H6-I6) -> 1
A7: F3 | B7: 기본 | C7: 여 | D7: ='분류 기준'!$C$5&"cm 미만" -> 158cm 미만 | E7: ="BMI "&'분류 기준'!$C$10&" 이상" -> BMI 23 이상 | F7: 앉은키가 작아 등받이 어깨 줄이 닿는 위치가 달라질 수 있음 → 거북목·정자세의 어깨 줄 값 확인; 압력이 커서 포화(최댓값 고정) 여부, 접촉 면적이 넓을 때의 좌우 비율 확인 | G7: 2 | H7: 1 | I7: =COUNTIF('참가자 명단'!$H$6:$H$55,$A7)+COUNTIF('참가자 명단'!$I$6:$I$55,$A7) -> 0 | J7: =MAX(0,H7-I7) -> 1
A8: F4 | B8: 기본 | C8: 여 | D8: ='분류 기준'!$C$5&"~"&'분류 기준'!$D$5&"cm 미만" -> 158~165cm 미만 | E8: ="BMI "&'분류 기준'!$C$9&" 미만" -> BMI 18.5 미만 | F8: 압력이 약해 앉지 않음·앞으로 숙이기와 구분되는지, 반응 채널 수 확인 | G8: 2 | H8: 1 | I8: =COUNTIF('참가자 명단'!$H$6:$H$55,$A8)+COUNTIF('참가자 명단'!$I$6:$I$55,$A8) -> 0 | J8: =MAX(0,H8-I8) -> 1
A9: F5 | B9: 기본 | C9: 여 | D9: ='분류 기준'!$C$5&"~"&'분류 기준'!$D$5&"cm 미만" -> 158~165cm 미만 | E9: ="BMI "&'분류 기준'!$C$9&"~"&'분류 기준'!$C$10&" 미만" -> BMI 18.5~23 미만 | F9: 기준 케이스(키·체형 모두 중간) — 합격 기준과 모델 분포의 중심 | G9: 1 | H9: 1 | I9: =COUNTIF('참가자 명단'!$H$6:$H$55,$A9)+COUNTIF('참가자 명단'!$I$6:$I$55,$A9) -> 0 | J9: =MAX(0,H9-I9) -> 1
A10: F6 | B10: 기본 | C10: 여 | D10: ='분류 기준'!$C$5&"~"&'분류 기준'!$D$5&"cm 미만" -> 158~165cm 미만 | E10: ="BMI "&'분류 기준'!$C$10&" 이상" -> BMI 23 이상 | F10: 압력이 커서 포화(최댓값 고정) 여부, 접촉 면적이 넓을 때의 좌우 비율 확인 | G10: 2 | H10: 1 | I10: =COUNTIF('참가자 명단'!$H$6:$H$55,$A10)+COUNTIF('참가자 명단'!$I$6:$I$55,$A10) -> 0 | J10: =MAX(0,H10-I10) -> 1
A11: F7 | B11: 기본 | C11: 여 | D11: ='분류 기준'!$D$5&"cm 이상" -> 165cm 이상 | E11: ="BMI "&'분류 기준'!$C$9&" 미만" -> BMI 18.5 미만 | F11: 앉은키가 커서 어깨가 매트 위로 벗어날 수 있음, 허벅지·무릎 줄 접촉 증가 → 앞으로 숙이기 기준(엉덩이 비중) 확인; 압력이 약해 앉지 않음·앞으로 숙이기와 구분되는지, 반응 채널 수 확인 | G11: 2 | H11: 1 | I11: =COUNTIF('참가자 명단'!$H$6:$H$55,$A11)+COUNTIF('참가자 명단'!$I$6:$I$55,$A11) -> 0 | J11: =MAX(0,H11-I11) -> 1
A12: F8 | B12: 기본 | C12: 여 | D12: ='분류 기준'!$D$5&"cm 이상" -> 165cm 이상 | E12: ="BMI "&'분류 기준'!$C$9&"~"&'분류 기준'!$C$10&" 미만" -> BMI 18.5~23 미만 | F12: 앉은키가 커서 어깨가 매트 위로 벗어날 수 있음, 허벅지·무릎 줄 접촉 증가 → 앞으로 숙이기 기준(엉덩이 비중) 확인 | G12: 2 | H12: 1 | I12: =COUNTIF('참가자 명단'!$H$6:$H$55,$A12)+COUNTIF('참가자 명단'!$I$6:$I$55,$A12) -> 0 | J12: =MAX(0,H12-I12) -> 1
A13: F9 | B13: 기본 | C13: 여 | D13: ='분류 기준'!$D$5&"cm 이상" -> 165cm 이상 | E13: ="BMI "&'분류 기준'!$C$10&" 이상" -> BMI 23 이상 | F13: 앉은키가 커서 어깨가 매트 위로 벗어날 수 있음, 허벅지·무릎 줄 접촉 증가 → 앞으로 숙이기 기준(엉덩이 비중) 확인; 압력이 커서 포화(최댓값 고정) 여부, 접촉 면적이 넓을 때의 좌우 비율 확인 | G13: 1 | H13: 1 | I13: =COUNTIF('참가자 명단'!$H$6:$H$55,$A13)+COUNTIF('참가자 명단'!$I$6:$I$55,$A13) -> 0 | J13: =MAX(0,H13-I13) -> 1
A14: M1 | B14: 기본 | C14: 남 | D14: ='분류 기준'!$C$6&"cm 미만" -> 170cm 미만 | E14: ="BMI "&'분류 기준'!$C$9&" 미만" -> BMI 18.5 미만 | F14: 앉은키가 작아 등받이 어깨 줄이 닿는 위치가 달라질 수 있음 → 거북목·정자세의 어깨 줄 값 확인; 압력이 약해 앉지 않음·앞으로 숙이기와 구분되는지, 반응 채널 수 확인 | G14: 1 | H14: 1 | I14: =COUNTIF('참가자 명단'!$H$6:$H$55,$A14)+COUNTIF('참가자 명단'!$I$6:$I$55,$A14) -> 0 | J14: =MAX(0,H14-I14) -> 1
A15: M2 | B15: 기본 | C15: 남 | D15: ='분류 기준'!$C$6&"cm 미만" -> 170cm 미만 | E15: ="BMI "&'분류 기준'!$C$9&"~"&'분류 기준'!$C$10&" 미만" -> BMI 18.5~23 미만 | F15: 앉은키가 작아 등받이 어깨 줄이 닿는 위치가 달라질 수 있음 → 거북목·정자세의 어깨 줄 값 확인 | G15: 2 | H15: 1 | I15: =COUNTIF('참가자 명단'!$H$6:$H$55,$A15)+COUNTIF('참가자 명단'!$I$6:$I$55,$A15) -> 0 | J15: =MAX(0,H15-I15) -> 1
A16: M3 | B16: 기본 | C16: 남 | D16: ='분류 기준'!$C$6&"cm 미만" -> 170cm 미만 | E16: ="BMI "&'분류 기준'!$C$10&" 이상" -> BMI 23 이상 | F16: 앉은키가 작아 등받이 어깨 줄이 닿는 위치가 달라질 수 있음 → 거북목·정자세의 어깨 줄 값 확인; 압력이 커서 포화(최댓값 고정) 여부, 접촉 면적이 넓을 때의 좌우 비율 확인 | G16: 2 | H16: 1 | I16: =COUNTIF('참가자 명단'!$H$6:$H$55,$A16)+COUNTIF('참가자 명단'!$I$6:$I$55,$A16) -> 0 | J16: =MAX(0,H16-I16) -> 1
A17: M4 | B17: 기본 | C17: 남 | D17: ='분류 기준'!$C$6&"~"&'분류 기준'!$D$6&"cm 미만" -> 170~178cm 미만 | E17: ="BMI "&'분류 기준'!$C$9&" 미만" -> BMI 18.5 미만 | F17: 압력이 약해 앉지 않음·앞으로 숙이기와 구분되는지, 반응 채널 수 확인 | G17: 2 | H17: 1 | I17: =COUNTIF('참가자 명단'!$H$6:$H$55,$A17)+COUNTIF('참가자 명단'!$I$6:$I$55,$A17) -> 0 | J17: =MAX(0,H17-I17) -> 1
A18: M5 | B18: 기본 | C18: 남 | D18: ='분류 기준'!$C$6&"~"&'분류 기준'!$D$6&"cm 미만" -> 170~178cm 미만 | E18: ="BMI "&'분류 기준'!$C$9&"~"&'분류 기준'!$C$10&" 미만" -> BMI 18.5~23 미만 | F18: 기준 케이스(키·체형 모두 중간) — 합격 기준과 모델 분포의 중심 | G18: 1 | H18: 1 | I18: =COUNTIF('참가자 명단'!$H$6:$H$55,$A18)+COUNTIF('참가자 명단'!$I$6:$I$55,$A18) -> 0 | J18: =MAX(0,H18-I18) -> 1
A19: M6 | B19: 기본 | C19: 남 | D19: ='분류 기준'!$C$6&"~"&'분류 기준'!$D$6&"cm 미만" -> 170~178cm 미만 | E19: ="BMI "&'분류 기준'!$C$10&" 이상" -> BMI 23 이상 | F19: 압력이 커서 포화(최댓값 고정) 여부, 접촉 면적이 넓을 때의 좌우 비율 확인 | G19: 2 | H19: 1 | I19: =COUNTIF('참가자 명단'!$H$6:$H$55,$A19)+COUNTIF('참가자 명단'!$I$6:$I$55,$A19) -> 0 | J19: =MAX(0,H19-I19) -> 1
A20: M7 | B20: 기본 | C20: 남 | D20: ='분류 기준'!$D$6&"cm 이상" -> 178cm 이상 | E20: ="BMI "&'분류 기준'!$C$9&" 미만" -> BMI 18.5 미만 | F20: 앉은키가 커서 어깨가 매트 위로 벗어날 수 있음, 허벅지·무릎 줄 접촉 증가 → 앞으로 숙이기 기준(엉덩이 비중) 확인; 압력이 약해 앉지 않음·앞으로 숙이기와 구분되는지, 반응 채널 수 확인 | G20: 2 | H20: 1 | I20: =COUNTIF('참가자 명단'!$H$6:$H$55,$A20)+COUNTIF('참가자 명단'!$I$6:$I$55,$A20) -> 0 | J20: =MAX(0,H20-I20) -> 1
A21: M8 | B21: 기본 | C21: 남 | D21: ='분류 기준'!$D$6&"cm 이상" -> 178cm 이상 | E21: ="BMI "&'분류 기준'!$C$9&"~"&'분류 기준'!$C$10&" 미만" -> BMI 18.5~23 미만 | F21: 앉은키가 커서 어깨가 매트 위로 벗어날 수 있음, 허벅지·무릎 줄 접촉 증가 → 앞으로 숙이기 기준(엉덩이 비중) 확인 | G21: 2 | H21: 1 | I21: =COUNTIF('참가자 명단'!$H$6:$H$55,$A21)+COUNTIF('참가자 명단'!$I$6:$I$55,$A21) -> 0 | J21: =MAX(0,H21-I21) -> 1
A22: M9 | B22: 기본 | C22: 남 | D22: ='분류 기준'!$D$6&"cm 이상" -> 178cm 이상 | E22: ="BMI "&'분류 기준'!$C$10&" 이상" -> BMI 23 이상 | F22: 앉은키가 커서 어깨가 매트 위로 벗어날 수 있음, 허벅지·무릎 줄 접촉 증가 → 앞으로 숙이기 기준(엉덩이 비중) 확인; 압력이 커서 포화(최댓값 고정) 여부, 접촉 면적이 넓을 때의 좌우 비율 확인 | G22: 1 | H22: 1 | I22: =COUNTIF('참가자 명단'!$H$6:$H$55,$A22)+COUNTIF('참가자 명단'!$I$6:$I$55,$A22) -> 1 | J22: =MAX(0,H22-I22) -> 0
A23: E01 | B23: 확장 | C23: 여 | D23: 150cm 미만 | E23: 상관없음 | F23: 키가 매우 작을 때 어깨 줄·무릎 줄이 매트 범위를 벗어나는지, 센서 접촉 한계 | G23: 3 | H23: 1 | I23: =COUNTIF('참가자 명단'!$H$6:$H$55,$A23)+COUNTIF('참가자 명단'!$I$6:$I$55,$A23) -> 0 | J23: =MAX(0,H23-I23) -> 1
A24: E02 | B24: 확장 | C24: 여 | D24: 172cm 이상 | E24: 상관없음 | F24: 어깨가 매트 위로 벗어날 때 거북목·정자세 구분이 유지되는지 | G24: 3 | H24: 1 | I24: =COUNTIF('참가자 명단'!$H$6:$H$55,$A24)+COUNTIF('참가자 명단'!$I$6:$I$55,$A24) -> 0 | J24: =MAX(0,H24-I24) -> 1
A25: E03 | B25: 확장 | C25: 남 | D25: 165cm 미만 | E25: 상관없음 | F25: 작은 남성 — 성별 × 키 교차, 방석 접촉 범위 | G25: 3 | H25: 1 | I25: =COUNTIF('참가자 명단'!$H$6:$H$55,$A25)+COUNTIF('참가자 명단'!$I$6:$I$55,$A25) -> 0 | J25: =MAX(0,H25-I25) -> 1
A26: E04 | B26: 확장 | C26: 남 | D26: 188cm 이상 | E26: 상관없음 | F26: 매우 큰 남성 — 무릎 줄 접촉, 어깨 줄 벗어남 | G26: 3 | H26: 1 | I26: =COUNTIF('참가자 명단'!$H$6:$H$55,$A26)+COUNTIF('참가자 명단'!$I$6:$I$55,$A26) -> 0 | J26: =MAX(0,H26-I26) -> 1
A27: E05 | B27: 확장 | C27: 여 | D27: 상관없음 | E27: BMI 17.5 미만 | F27: 압력이 매우 약할 때 앉지 않음과 분리되는지 | G27: 3 | H27: 1 | I27: =COUNTIF('참가자 명단'!$H$6:$H$55,$A27)+COUNTIF('참가자 명단'!$I$6:$I$55,$A27) -> 0 | J27: =MAX(0,H27-I27) -> 1
A28: E06 | B28: 확장 | C28: 남 | D28: 상관없음 | E28: BMI 17.5 미만 | F28: 압력이 매우 약할 때 앉지 않음과 분리되는지 | G28: 3 | H28: 1 | I28: =COUNTIF('참가자 명단'!$H$6:$H$55,$A28)+COUNTIF('참가자 명단'!$I$6:$I$55,$A28) -> 0 | J28: =MAX(0,H28-I28) -> 1
A29: E07 | B29: 확장 | C29: 여 | D29: 상관없음 | E29: BMI 28 이상 | F29: 압력 포화(최댓값 고정)와 넓은 접촉 | G29: 3 | H29: 1 | I29: =COUNTIF('참가자 명단'!$H$6:$H$55,$A29)+COUNTIF('참가자 명단'!$I$6:$I$55,$A29) -> 0 | J29: =MAX(0,H29-I29) -> 1
A30: E08 | B30: 확장 | C30: 남 | D30: 상관없음 | E30: BMI 28 이상 | F30: 포화 확인 — 현재 최대 체형(남성 180cm·BMI 26)보다 더 큰 쪽 | G30: 3 | H30: 1 | I30: =COUNTIF('참가자 명단'!$H$6:$H$55,$A30)+COUNTIF('참가자 명단'!$I$6:$I$55,$A30) -> 0 | J30: =MAX(0,H30-I30) -> 1
A31: E09 | B31: 확장 | C31: 무관 | D31: 무관 | E31: 평소 깊이 앉는 습관 (등을 등받이에 항상 붙임) | F31: 정자세에서 등받이 접촉이 큰 경우의 기준 상한 확인 | G31: 2 | H31: 1 | I31: =COUNTIF('참가자 명단'!$H$6:$H$55,$A31)+COUNTIF('참가자 명단'!$I$6:$I$55,$A31) -> 0 | J31: =MAX(0,H31-I31) -> 1
A32: E10 | B32: 확장 | C32: 무관 | D32: 무관 | E32: 평소 걸터앉는 습관 (엉덩이를 의자 앞쪽에) | F32: 등받이 접촉이 약한 사람의 정자세·거북목·앞으로 숙이기 구분 | G32: 2 | H32: 1 | I32: =COUNTIF('참가자 명단'!$H$6:$H$55,$A32)+COUNTIF('참가자 명단'!$I$6:$I$55,$A32) -> 0 | J32: =MAX(0,H32-I32) -> 1
A33: E11 | B33: 확장 | C33: 무관 | D33: 무관 | E33: 평소 오른다리 꼬는 습관 | F33: 좌우 비대칭 습관이 정자세 기준(방석 좌우 40~60%)을 깨는지 | G33: 2 | H33: 1 | I33: =COUNTIF('참가자 명단'!$H$6:$H$55,$A33)+COUNTIF('참가자 명단'!$I$6:$I$55,$A33) -> 0 | J33: =MAX(0,H33-I33) -> 1
A34: E12 | B34: 확장 | C34: 무관 | D34: 무관 | E34: 평소 왼다리 꼬는 습관 | F34: 좌우 비대칭 습관이 정자세 기준(방석 좌우 40~60%)을 깨는지 | G34: 2 | H34: 1 | I34: =COUNTIF('참가자 명단'!$H$6:$H$55,$A34)+COUNTIF('참가자 명단'!$I$6:$I$55,$A34) -> 0 | J34: =MAX(0,H34-I34) -> 1
... A39: E17 | B39: 확장 | C39: 무관 | D39: 무관 | E39: 연령대 50대 이상 | F39: 현재 20대만 있는 연령 편중 해소 | G39: 3 | H39: 1 | I39: =COUNTIF('참가자 명단'!$H$6:$H$55,$A39)+COUNTIF('참가자 명단'!$I$6:$I$55,$A39) -> 0 | J39: =MAX(0,H39-I39) -> 1
A41: 합계 (전체) | H41: =SUM(H5:H39) -> 35 | I41: =SUM(I5:I39) -> 1 | J41: =SUM(J5:J39) -> 34
A42: 합계 (우선순위 1) | H42: =SUMIFS(H5:H39,G5:G39,1) -> 6 | I42: =SUMIFS(I5:I39,G5:G39,1) -> 1 | J42: =SUMIFS(J5:J39,G5:G39,1) -> 5
A44: 확보 인원 = '참가자 명단'의 기본 케이스(H열, 키·체중으로 자동 판정) + 추가 조건 케이스(I열, E01~E17 직접 입력)에 이 ID가 나온 횟수입니다. 한 사람이 둘 다 해당하면 양쪽에 집계됩니다.
A45: 우선순위: 1=필수(체격 양 끝과 중앙), 2=권장, 3=여유가 있을 때. 우선순위·목표 인원은 파란 글씨라 직접 바꿔도 됩니다.
A46: E13·E14·E15는 새 사람이 아니라 기존 참가자를 다른 조건에서 다시 측정하는 케이스입니다.
A47: 기본 18케이스의 구간 경계는 '분류 기준' 시트에서 바꿉니다. 팀의 기존 케이스 매트릭스와 경계가 다르면 그쪽에 맞추세요.

Sheet 참가자 명단
A1: 참가자 명단
A2: 노란 칸에 입력하세요. BMI·케이스·합격 현황은 자동 계산됩니다. 4~6행은 이미 수집된 4명(2026-10-18 커밋 27c67e4)입니다.
A5: 참가자 ID | B5: person (파일명 이름, 영문 소문자) | C5: 성별 | D5: 키 (cm) | E5: 체중 (kg) | F5: 연령대 | G5: BMI (자동) | H5: 기본 케이스 (자동) | I5: 추가 조건 케이스 (직접 입력, 예: E10) | J5: 합격 파일 수 (자동) | K5: 합격한 자세 종류 (8종 중, 자동) | L5: 비고
A6: P01 | B6: dahye | C6: 여 | F6: 20대 | G6: =IF(AND(ISNUMBER(D6),ISNUMBER(E6)),ROUND(E6/(D6/100)^2,1),"") | H6: =IF(OR($C6="",$G6=""),"",INDEX('분류 기준'!$B$5:$B$6,MATCH($C6,'분류 기준'!$A$5:$A$6,0))&((IF($D6<INDEX('분류 기준'!$C$5:$C$6,MATCH($C6,'분류 기준'!$A$5:$A$6,0)),1,IF($D6<INDEX('분류 기준'!$D$5:$D$6,MATCH($C6,'분류 기준'!$A$5:$A$6,0)),2,3))-1)*3+IF($G6<'분류 기준'!$C$9,1,IF($G6<'분류 기준'!$C$10,2,3)))) | J6: =IF($B6="","",COUNTIFS('수집 현황'!$B$6:$B$105,$B6,'수집 현황'!$AA$6:$AA$105,"PASS")) -> 7 | K6: =IF($B6="","",COUNTIF('자세 수집 현황'!$C6:$J6,">0")) -> 7 | L6: 키·체중을 입력하면 케이스가 자동으로 정해집니다
A7: P02 | B7: aro | C7: 여 | F7: 20대 | G7: =IF(AND(ISNUMBER(D7),ISNUMBER(E7)),ROUND(E7/(D7/100)^2,1),"") | H7: =IF(OR($C7="",$G7=""),"",INDEX('분류 기준'!$B$5:$B$6,MATCH($C7,'분류 기준'!$A$5:$A$6,0))&((IF($D7<INDEX('분류 기준'!$C$5:$C$6,MATCH($C7,'분류 기준'!$A$5:$A$6,0)),1,IF($D7<INDEX('분류 기준'!$D$5:$D$6,MATCH($C7,'분류 기준'!$A$5:$A$6,0)),2,3))-1)*3+IF($G7<'분류 기준'!$C$9,1,IF($G7<'분류 기준'!$C$10,2,3)))) | J7: =IF($B7="","",COUNTIFS('수집 현황'!$B$6:$B$105,$B7,'수집 현황'!$AA$6:$AA$105,"PASS")) -> 3 | K7: =IF($B7="","",COUNTIF('자세 수집 현황'!$C7:$J7,">0")) -> 3 | L7: 키·체중을 입력하면 케이스가 자동으로 정해집니다
A8: P03 | B8: yewon | C8: 여 | F8: 20대 | G8: =IF(AND(ISNUMBER(D8),ISNUMBER(E8)),ROUND(E8/(D8/100)^2,1),"") | H8: =IF(OR($C8="",$G8=""),"",INDEX('분류 기준'!$B$5:$B$6,MATCH($C8,'분류 기준'!$A$5:$A$6,0))&((IF($D8<INDEX('분류 기준'!$C$5:$C$6,MATCH($C8,'분류 기준'!$A$5:$A$6,0)),1,IF($D8<INDEX('분류 기준'!$D$5:$D$6,MATCH($C8,'분류 기준'!$A$5:$A$6,0)),2,3))-1)*3+IF($G8<'분류 기준'!$C$9,1,IF($G8<'분류 기준'!$C$10,2,3)))) | J8: =IF($B8="","",COUNTIFS('수집 현황'!$B$6:$B$105,$B8,'수집 현황'!$AA$6:$AA$105,"PASS")) -> 8 | K8: =IF($B8="","",COUNTIF('자세 수집 현황'!$C8:$J8,">0")) -> 8 | L8: 키·체중을 입력하면 케이스가 자동으로 정해집니다
A9: P04 | B9: junseo | C9: 남 | D9: 180 | E9: 85 | F9: 20대 | G9: =IF(AND(ISNUMBER(D9),ISNUMBER(E9)),ROUND(E9/(D9/100)^2,1),"") -> 26.2 | H9: =IF(OR($C9="",$G9=""),"",INDEX('분류 기준'!$B$5:$B$6,MATCH($C9,'분류 기준'!$A$5:$A$6,0))&((IF($D9<INDEX('분류 기준'!$C$5:$C$6,MATCH($C9,'분류 기준'!$A$5:$A$6,0)),1,IF($D9<INDEX('분류 기준'!$D$5:$D$6,MATCH($C9,'분류 기준'!$A$5:$A$6,0)),2,3))-1)*3+IF($G9<'분류 기준'!$C$9,1,IF($G9<'분류 기준'!$C$10,2,3)))) -> M9 | J9: =IF($B9="","",COUNTIFS('수집 현황'!$B$6:$B$105,$B9,'수집 현황'!$AA$6:$AA$105,"PASS")) -> 7 | K9: =IF($B9="","",COUNTIF('자세 수집 현황'!$C9:$J9,">0")) -> 7 | L9: 키·체중은 커밋 27c67e4 설명에 적힌 값 (예시 행)
G10: =IF(AND(ISNUMBER(D10),ISNUMBER(E10)),ROUND(E10/(D10/100)^2,1),"") | H10: =IF(OR($C10="",$G10=""),"",INDEX('분류 기준'!$B$5:$B$6,MATCH($C10,'분류 기준'!$A$5:$A$6,0))&((IF($D10<INDEX('분류 기준'!$C$5:$C$6,MATCH($C10,'분류 기준'!$A$5:$A$6,0)),1,IF($D10<INDEX('분류 기준'!$D$5:$D$6,MATCH($C10,'분류 기준'!$A$5:$A$6,0)),2,3))-1)*3+IF($G10<'분류 기준'!$C$9,1,IF($G10<'분류 기준'!$C$10,2,3)))) | J10: =IF($B10="","",COUNTIFS('수집 현황'!$B$6:$B$105,$B10,'수집 현황'!$AA$6:$AA$105,"PASS")) | K10: =IF($B10="","",COUNTIF('자세 수집 현황'!$C10:$J10,">0"))
G11: =IF(AND(ISNUMBER(D11),ISNUMBER(E11)),ROUND(E11/(D11/100)^2,1),"") | H11: =IF(OR($C11="",$G11=""),"",INDEX('분류 기준'!$B$5:$B$6,MATCH($C11,'분류 기준'!$A$5:$A$6,0))&((IF($D11<INDEX('분류 기준'!$C$5:$C$6,MATCH($C11,'분류 기준'!$A$5:$A$6,0)),1,IF($D11<INDEX('분류 기준'!$D$5:$D$6,MATCH($C11,'분류 기준'!$A$5:$A$6,0)),2,3))-1)*3+IF($G11<'분류 기준'!$C$9,1,IF($G11<'분류 기준'!$C$10,2,3)))) | J11: =IF($B11="","",COUNTIFS('수집 현황'!$B$6:$B$105,$B11,'수집 현황'!$AA$6:$AA$105,"PASS")) | K11: =IF($B11="","",COUNTIF('자세 수집 현황'!$C11:$J11,">0"))
G12: =IF(AND(ISNUMBER(D12),ISNUMBER(E12)),ROUND(E12/(D12/100)^2,1),"") | H12: =IF(OR($C12="",$G12=""),"",INDEX('분류 기준'!$B$5:$B$6,MATCH($C12,'분류 기준'!$A$5:$A$6,0))&((IF($D12<INDEX('분류 기준'!$C$5:$C$6,MATCH($C12,'분류 기준'!$A$5:$A$6,0)),1,IF($D12<INDEX('분류 기준'!$D$5:$D$6,MATCH($C12,'분류 기준'!$A$5:$A$6,0)),2,3))-1)*3+IF($G12<'분류 기준'!$C$9,1,IF($G12<'분류 기준'!$C$10,2,3)))) | J12: =IF($B12="","",COUNTIFS('수집 현황'!$B$6:$B$105,$B12,'수집 현황'!$AA$6:$AA$105,"PASS")) | K12: =IF($B12="","",COUNTIF('자세 수집 현황'!$C12:$J12,">0"))
G13: =IF(AND(ISNUMBER(D13),ISNUMBER(E13)),ROUND(E13/(D13/100)^2,1),"") | H13: =IF(OR($C13="",$G13=""),"",INDEX('분류 기준'!$B$5:$B$6,MATCH($C13,'분류 기준'!$A$5:$A$6,0))&((IF($D13<INDEX('분류 기준'!$C$5:$C$6,MATCH($C13,'분류 기준'!$A$5:$A$6,0)),1,IF($D13<INDEX('분류 기준'!$D$5:$D$6,MATCH($C13,'분류 기준'!$A$5:$A$6,0)),2,3))-1)*3+IF($G13<'분류 기준'!$C$9,1,IF($G13<'분류 기준'!$C$10,2,3)))) | J13: =IF($B13="","",COUNTIFS('수집 현황'!$B$6:$B$105,$B13,'수집 현황'!$AA$6:$AA$105,"PASS")) | K13: =IF($B13="","",COUNTIF('자세 수집 현황'!$C13:$J13,">0"))
G14: =IF(AND(ISNUMBER(D14),ISNUMBER(E14)),ROUND(E14/(D14/100)^2,1),"") | H14: =IF(OR($C14="",$G14=""),"",INDEX('분류 기준'!$B$5:$B$6,MATCH($C14,'분류 기준'!$A$5:$A$6,0))&((IF($D14<INDEX('분류 기준'!$C$5:$C$6,MATCH($C14,'분류 기준'!$A$5:$A$6,0)),1,IF($D14<INDEX('분류 기준'!$D$5:$D$6,MATCH($C14,'분류 기준'!$A$5:$A$6,0)),2,3))-1)*3+IF($G14<'분류 기준'!$C$9,1,IF($G14<'분류 기준'!$C$10,2,3)))) | J14: =IF($B14="","",COUNTIFS('수집 현황'!$B$6:$B$105,$B14,'수집 현황'!$AA$6:$AA$105,"PASS")) | K14: =IF($B14="","",COUNTIF('자세 수집 현황'!$C14:$J14,">0"))
G15: =IF(AND(ISNUMBER(D15),ISNUMBER(E15)),ROUND(E15/(D15/100)^2,1),"") | H15: =IF(OR($C15="",$G15=""),"",INDEX('분류 기준'!$B$5:$B$6,MATCH($C15,'분류 기준'!$A$5:$A$6,0))&((IF($D15<INDEX('분류 기준'!$C$5:$C$6,MATCH($C15,'분류 기준'!$A$5:$A$6,0)),1,IF($D15<INDEX('분류 기준'!$D$5:$D$6,MATCH($C15,'분류 기준'!$A$5:$A$6,0)),2,3))-1)*3+IF($G15<'분류 기준'!$C$9,1,IF($G15<'분류 기준'!$C$10,2,3)))) | J15: =IF($B15="","",COUNTIFS('수집 현황'!$B$6:$B$105,$B15,'수집 현황'!$AA$6:$AA$105,"PASS")) | K15: =IF($B15="","",COUNTIF('자세 수집 현황'!$C15:$J15,">0"))
G16: =IF(AND(ISNUMBER(D16),ISNUMBER(E16)),ROUND(E16/(D16/100)^2,1),"") | H16: =IF(OR($C16="",$G16=""),"",INDEX('분류 기준'!$B$5:$B$6,MATCH($C16,'분류 기준'!$A$5:$A$6,0))&((IF($D16<INDEX('분류 기준'!$C$5:$C$6,MATCH($C16,'분류 기준'!$A$5:$A$6,0)),1,IF($D16<INDEX('분류 기준'!$D$5:$D$6,MATCH($C16,'분류 기준'!$A$5:$A$6,0)),2,3))-1)*3+IF($G16<'분류 기준'!$C$9,1,IF($G16<'분류 기준'!$C$10,2,3)))) | J16: =IF($B16="","",COUNTIFS('수집 현황'!$B$6:$B$105,$B16,'수집 현황'!$AA$6:$AA$105,"PASS")) | K16: =IF($B16="","",COUNTIF('자세 수집 현황'!$C16:$J16,">0"))
G17: =IF(AND(ISNUMBER(D17),ISNUMBER(E17)),ROUND(E17/(D17/100)^2,1),"") | H17: =IF(OR($C17="",$G17=""),"",INDEX('분류 기준'!$B$5:$B$6,MATCH($C17,'분류 기준'!$A$5:$A$6,0))&((IF($D17<INDEX('분류 기준'!$C$5:$C$6,MATCH($C17,'분류 기준'!$A$5:$A$6,0)),1,IF($D17<INDEX('분류 기준'!$D$5:$D$6,MATCH($C17,'분류 기준'!$A$5:$A$6,0)),2,3))-1)*3+IF($G17<'분류 기준'!$C$9,1,IF($G17<'분류 기준'!$C$10,2,3)))) | J17: =IF($B17="","",COUNTIFS('수집 현황'!$B$6:$B$105,$B17,'수집 현황'!$AA$6:$AA$105,"PASS")) | K17: =IF($B17="","",COUNTIF('자세 수집 현황'!$C17:$J17,">0"))
G18: =IF(AND(ISNUMBER(D18),ISNUMBER(E18)),ROUND(E18/(D18/100)^2,1),"") | H18: =IF(OR($C18="",$G18=""),"",INDEX('분류 기준'!$B$5:$B$6,MATCH($C18,'분류 기준'!$A$5:$A$6,0))&((IF($D18<INDEX('분류 기준'!$C$5:$C$6,MATCH($C18,'분류 기준'!$A$5:$A$6,0)),1,IF($D18<INDEX('분류 기준'!$D$5:$D$6,MATCH($C18,'분류 기준'!$A$5:$A$6,0)),2,3))-1)*3+IF($G18<'분류 기준'!$C$9,1,IF($G18<'분류 기준'!$C$10,2,3)))) | J18: =IF($B18="","",COUNTIFS('수집 현황'!$B$6:$B$105,$B18,'수집 현황'!$AA$6:$AA$105,"PASS")) | K18: =IF($B18="","",COUNTIF('자세 수집 현황'!$C18:$J18,">0"))
G19: =IF(AND(ISNUMBER(D19),ISNUMBER(E19)),ROUND(E19/(D19/100)^2,1),"") | H19: =IF(OR($C19="",$G19=""),"",INDEX('분류 기준'!$B$5:$B$6,MATCH($C19,'분류 기준'!$A$5:$A$6,0))&((IF($D19<INDEX('분류 기준'!$C$5:$C$6,MATCH($C19,'분류 기준'!$A$5:$A$6,0)),1,IF($D19<INDEX('분류 기준'!$D$5:$D$6,MATCH($C19,'분류 기준'!$A$5:$A$6,0)),2,3))-1)*3+IF($G19<'분류 기준'!$C$9,1,IF($G19<'분류 기준'!$C$10,2,3)))) | J19: =IF($B19="","",COUNTIFS('수집 현황'!$B$6:$B$105,$B19,'수집 현황'!$AA$6:$AA$105,"PASS")) | K19: =IF($B19="","",COUNTIF('자세 수집 현황'!$C19:$J19,">0"))
G20: =IF(AND(ISNUMBER(D20),ISNUMBER(E20)),ROUND(E20/(D20/100)^2,1),"") | H20: =IF(OR($C20="",$G20=""),"",INDEX('분류 기준'!$B$5:$B$6,MATCH($C20,'분류 기준'!$A$5:$A$6,0))&((IF($D20<INDEX('분류 기준'!$C$5:$C$6,MATCH($C20,'분류 기준'!$A$5:$A$6,0)),1,IF($D20<INDEX('분류 기준'!$D$5:$D$6,MATCH($C20,'분류 기준'!$A$5:$A$6,0)),2,3))-1)*3+IF($G20<'분류 기준'!$C$9,1,IF($G20<'분류 기준'!$C$10,2,3)))) | J20: =IF($B20="","",COUNTIFS('수집 현황'!$B$6:$B$105,$B20,'수집 현황'!$AA$6:$AA$105,"PASS")) | K20: =IF($B20="","",COUNTIF('자세 수집 현황'!$C20:$J20,">0"))
G21: =IF(AND(ISNUMBER(D21),ISNUMBER(E21)),ROUND(E21/(D21/100)^2,1),"") | H21: =IF(OR($C21="",$G21=""),"",INDEX('분류 기준'!$B$5:$B$6,MATCH($C21,'분류 기준'!$A$5:$A$6,0))&((IF($D21<INDEX('분류 기준'!$C$5:$C$6,MATCH($C21,'분류 기준'!$A$5:$A$6,0)),1,IF($D21<INDEX('분류 기준'!$D$5:$D$6,MATCH($C21,'분류 기준'!$A$5:$A$6,0)),2,3))-1)*3+IF($G21<'분류 기준'!$C$9,1,IF($G21<'분류 기준'!$C$10,2,3)))) | J21: =IF($B21="","",COUNTIFS('수집 현황'!$B$6:$B$105,$B21,'수집 현황'!$AA$6:$AA$105,"PASS")) | K21: =IF($B21="","",COUNTIF('자세 수집 현황'!$C21:$J21,">0"))
... G55: =IF(AND(ISNUMBER(D55),ISNUMBER(E55)),ROUND(E55/(D55/100)^2,1),"") | H55: =IF(OR($C55="",$G55=""),"",INDEX('분류 기준'!$B$5:$B$6,MATCH($C55,'분류 기준'!$A$5:$A$6,0))&((IF($D55<INDEX('분류 기준'!$C$5:$C$6,MATCH($C55,'분류 기준'!$A$5:$A$6,0)),1,IF($D55<INDEX('분류 기준'!$D$5:$D$6,MATCH($C55,'분류 기준'!$A$5:$A$6,0)),2,3))-1)*3+IF($G55<'분류 기준'!$C$9,1,IF($G55<'분류 기준'!$C$10,2,3)))) | J55: =IF($B55="","",COUNTIFS('수집 현황'!$B$6:$B$105,$B55,'수집 현황'!$AA$6:$AA$105,"PASS")) | K55: =IF($B55="","",COUNTIF('자세 수집 현황'!$C55:$J55,">0"))
A57: 범례: 노란 칸 = 직접 입력(파란 글씨), 흰 칸 = 자동 계산. 4행(P04 junseo)은 입력 형식을 보여 주는 예시이기도 합니다. 개인 키·체중은 팀 내부에서만 공유하세요.

Sheet 분류 기준
A1: 참가자 분류 기준
A2: 섭외 케이스 ID(F1~F9 / M1~M9)를 자동으로 정하는 기준값입니다. 파란 글씨 숫자를 바꾸면 모든 시트가 따라 바뀝니다.
A4: 성별 | B4: 접두 | C4: 키 '작음' 기준 (cm 미만) | D4: 키 '큼' 기준 (cm 이상)
A5: 여 | B5: F | C5: 158 | D5: 165
A6: 남 | B6: M | C6: 170 | D6: 178
A8: 체형 구분 | C8: BMI 기준
A9: 마름 (BMI 미만) | C9: 18.5
A10: 통통 (BMI 이상) | C10: 23
A12: 케이스 ID = 접두 + ((키 구간 − 1) × 3 + 체형 구간). 키 구간: 1=작음, 2=보통, 3=큼. 체형 구간: 1=마름, 2=보통, 3=통통. 예) 남성 180cm·BMI 26 → M9.
A13: BMI는 체중(kg) ÷ 키(m)²로 계산하며 몸집을 나누기 위한 숫자일 뿐, 건강 상태를 판단하는 값이 아닙니다.
A14: 키 기준(여 158/165, 남 170/178)은 이 시트에서 정한 초안입니다. 팀의 기존 '실측 참가자 섭외 케이스 매트릭스'(F1~F9/M1~M9)와 구간 경계가 다르면 여기 숫자만 맞추세요.

Sheet 합격 기준
A1: 자세별 합격 기준 (방석 + 등받이)
A2: 참가자에게 읽어 줄 자세 요령, 자세별로 기대하는 압력 패턴, 수치 기준, 불합격일 때의 조치입니다. 수치 기준은 '합격 기준 수치표'와 연동됩니다.
A3: 좌우는 2026-10-18 뒤집은 매트 기준입니다. 방석은 번호가 작을수록 사용자의 왼쪽, 등받이는 번호가 작을수록 오른쪽. 방석 좌우는 팀 확인에 따랐고 탭 테스트로 한 번 더 확인하세요.
A5: 코드 | B5: 자세 | C5: 자세 요령 (참가자에게 읽어 줄 문구) | D5: 방석에서 기대하는 것 (엉덩이·허벅지·무릎) | E5: 등받이에서 기대하는 것 (허리·중간·어깨 줄) | F5: 수치 기준 (수치표 연동) | G5: 흔한 실패와 조치
A6: p0 | B6: not_sitting (앉지 않음) | C6: 의자에서 완전히 일어나 서 있으세요. 손이나 가방도 방석·등받이에 닿지 않게 해 주세요. | D6: 모든 채널이 0 근처. 관찰: 2개 파일 모두 총압력 0. | E6: 모든 채널이 0 근처. 관찰: 2개 파일 모두 총압력 0. | F6: =IF('합격 기준 수치표'!D6="","","• 방석 총압력 ≥ "&'합격 기준 수치표'!D6&" 원시값 합"&CHAR(10))&IF('합격 기준 수치표'!E6="","","• 방석 총압력 ≤ "&'합격 기준 수치표'!E6&" 원시값 합"&CHAR(10))&IF('합격 기준 수치표'!F6="","","• 등받이 총압력 ≥ "&'합격 기준 수치표'!F6&" 원시값 합"&CHAR(10))&IF('합격 기준 수치표'!G6="","","• 등받이 총압력 ≤ "&'합격 기준 수치표'!G6&" 원시값 합"&CHAR(10))&IF('합격 기준 수치표'!H6="","","• 엉덩이 줄 비중 ≥ "&'합격 기준 수치표'!H6&" %"&CHAR(10))&IF('합격 기준 수치표'!I6="","","• 엉덩이 줄 비중 ≤ "&'합격 기준 수치표'!I6&" %"&CHAR(10))&IF('합격 기준 수치표'!J6="","","• 방석 오른쪽 비율 ≥ "&'합격 기준 수치표'!J6&" %"&CHAR(10))&IF('합격 기준 수치표'!K6="","","• 방석 오른쪽 비율 ≤ "&'합격 기준 수치표'!K6&" %"&CHAR(10))&IF('합격 기준 수치표'!L6="","","• 등받이 오른쪽 비율 ≥ "&'합격 기준 수치표'!L6&" %"&CHAR(10))&IF('합격 기준 수치표'!M6="","","• 등받이 오른쪽 비율 ≤ "&'합격 기준 수치표'!M6&" %"&CHAR(10))&IF('합격 기준 수치표'!N6="","","• 등받이 어깨 줄 비중 ≥ "&'합격 기준 수치표'!N6&" %"&CHAR(10))&IF('합격 기준 수치표'!O6="","","• 등받이 어깨 줄 비중 ≤ "&'합격 기준 수치표'!O6&" %"&CHAR(10))&IF('합격 기준 수치표'!P6="","","• 등받이 반응 채널 수 ≥ "&'합격 기준 수치표'!P6&" 개"&CHAR(10))&IF('합격 기준 수치표'!Q6="","","• 등받이 반응 채널 수 ≤ "&'합격 기준 수치표'!Q6&" 개"&CHAR(10)) -> • 방석 총압력 ≤ 300 원시값 합 • 등받이 총압력 ≤ 100 원시값 합 | G6: 방석·등받이에 값이 남아 있으면(영점이 틀어졌거나 물건이 올라가 있음) 센서를 비운 상태에서 baseline을 다시 잡고 재측정. 수집 직전에 일어났다가 앉는 동작 때문에 앞부분에 값이 남을 수 있으니 카운트다운 후에 시작.
A7: p1 | B7: sitting_straight (정자세) | C7: 엉덩이를 의자 안쪽까지 넣고, 등을 등받이에 편하게 붙이세요. 시선은 정면, 양발은 바닥에 두세요. | D7: 좌우 균형(오른쪽 비율 40~60%, 관찰 45.2~55.5%). 엉덩이 줄 비중은 사람마다 달라 기준 없음(관찰 32.7~51.3%). | E7: 허리·중간 줄에 접촉(관찰 총압력 1,471~4,050). 어깨 줄은 사람에 따라 0~23%로 크게 달라 기준 없음. 등받이 좌우 비율도 사람마다 달라(44.7~100%) 기준 없음. | F7: =IF('합격 기준 수치표'!D7="","","• 방석 총압력 ≥ "&'합격 기준 수치표'!D7&" 원시값 합"&CHAR(10))&IF('합격 기준 수치표'!E7="","","• 방석 총압력 ≤ "&'합격 기준 수치표'!E7&" 원시값 합"&CHAR(10))&IF('합격 기준 수치표'!F7="","","• 등받이 총압력 ≥ "&'합격 기준 수치표'!F7&" 원시값 합"&CHAR(10))&IF('합격 기준 수치표'!G7="","","• 등받이 총압력 ≤ "&'합격 기준 수치표'!G7&" 원시값 합"&CHAR(10))&IF('합격 기준 수치표'!H7="","","• 엉덩이 줄 비중 ≥ "&'합격 기준 수치표'!H7&" %"&CHAR(10))&IF('합격 기준 수치표'!I7="","","• 엉덩이 줄 비중 ≤ "&'합격 기준 수치표'!I7&" %"&CHAR(10))&IF('합격 기준 수치표'!J7="","","• 방석 오른쪽 비율 ≥ "&'합격 기준 수치표'!J7&" %"&CHAR(10))&IF('합격 기준 수치표'!K7="","","• 방석 오른쪽 비율 ≤ "&'합격 기준 수치표'!K7&" %"&CHAR(10))&IF('합격 기준 수치표'!L7="","","• 등받이 오른쪽 비율 ≥ "&'합격 기준 수치표'!L7&" %"&CHAR(10))&IF('합격 기준 수치표'!M7="","","• 등받이 오른쪽 비율 ≤ "&'합격 기준 수치표'!M7&" %"&CHAR(10))&IF('합격 기준 수치표'!N7="","","• 등받이 어깨 줄 비중 ≥ "&'합격 기준 수치표'!N7&" %"&CHAR(10))&IF('합격 기준 수치표'!O7="","","• 등받이 어깨 줄 비중 ≤ "&'합격 기준 수치표'!O7&" %"&CHAR(10))&IF('합격 기준 수치표'!P7="","","• 등받이 반응 채널 수 ≥ "&'합격 기준 수치표'!P7&" 개"&CHAR(10))&IF('합격 기준 수치표'!Q7="","","• 등받이 반응 채널 수 ≤ "&'합격 기준 수치표'!Q7&" 개"&CHAR(10)) -> • 방석 총압력 ≥ 6000 원시값 합 • 등받이 총압력 ≥ 1000 원시값 합 • 방석 오른쪽 비율 ≥ 40 % • 방석 오른쪽 비율 ≤ 60 % • 등받이 반응 채널 수 ≥ 4 개 | G7: 한쪽으로 기울어짐(방석 오른쪽 비율 범위 밖) → 자세를 풀었다가 다시 앉아 재촬영. 등받이 총압력이 낮음 → 등이 등받이에 닿지 않은 것이니 등을 더 붙이게 하고, 그래도 같으면 매트 위치 확인.
A8: p2 | B8: lean_forward (앞으로 숙이기) | C8: 상체를 앞으로 숙여서 등이 등받이에서 완전히 떨어지게 하세요. 엉덩이는 의자에 그대로 두세요. | D8: 엉덩이 줄 비중이 줄고 허벅지·무릎 비중이 늘어남(관찰 엉덩이 18.2~29.5%, 정자세는 32.7~51.3%). 좌우는 균형(관찰 47.2~52.6%). | E8: 모든 채널 0. 관찰: 3개 파일 모두 총압력 0. | F8: =IF('합격 기준 수치표'!D8="","","• 방석 총압력 ≥ "&'합격 기준 수치표'!D8&" 원시값 합"&CHAR(10))&IF('합격 기준 수치표'!E8="","","• 방석 총압력 ≤ "&'합격 기준 수치표'!E8&" 원시값 합"&CHAR(10))&IF('합격 기준 수치표'!F8="","","• 등받이 총압력 ≥ "&'합격 기준 수치표'!F8&" 원시값 합"&CHAR(10))&IF('합격 기준 수치표'!G8="","","• 등받이 총압력 ≤ "&'합격 기준 수치표'!G8&" 원시값 합"&CHAR(10))&IF('합격 기준 수치표'!H8="","","• 엉덩이 줄 비중 ≥ "&'합격 기준 수치표'!H8&" %"&CHAR(10))&IF('합격 기준 수치표'!I8="","","• 엉덩이 줄 비중 ≤ "&'합격 기준 수치표'!I8&" %"&CHAR(10))&IF('합격 기준 수치표'!J8="","","• 방석 오른쪽 비율 ≥ "&'합격 기준 수치표'!J8&" %"&CHAR(10))&IF('합격 기준 수치표'!K8="","","• 방석 오른쪽 비율 ≤ "&'합격 기준 수치표'!K8&" %"&CHAR(10))&IF('합격 기준 수치표'!L8="","","• 등받이 오른쪽 비율 ≥ "&'합격 기준 수치표'!L8&" %"&CHAR(10))&IF('합격 기준 수치표'!M8="","","• 등받이 오른쪽 비율 ≤ "&'합격 기준 수치표'!M8&" %"&CHAR(10))&IF('합격 기준 수치표'!N8="","","• 등받이 어깨 줄 비중 ≥ "&'합격 기준 수치표'!N8&" %"&CHAR(10))&IF('합격 기준 수치표'!O8="","","• 등받이 어깨 줄 비중 ≤ "&'합격 기준 수치표'!O8&" %"&CHAR(10))&IF('합격 기준 수치표'!P8="","","• 등받이 반응 채널 수 ≥ "&'합격 기준 수치표'!P8&" 개"&CHAR(10))&IF('합격 기준 수치표'!Q8="","","• 등받이 반응 채널 수 ≤ "&'합격 기준 수치표'!Q8&" 개"&CHAR(10)) -> • 방석 총압력 ≥ 6000 원시값 합 • 등받이 총압력 ≤ 100 원시값 합 • 엉덩이 줄 비중 ≤ 32 % • 방석 오른쪽 비율 ≥ 40 % • 방석 오른쪽 비율 ≤ 60 % | G8: 등받이 총압력이 100을 넘음 → 등이 닿은 것이니 더 숙이게 하고 재촬영. 엉덩이 비중이 32%를 넘음 → 덜 숙인 것(정자세와 겹침)이니 재촬영. 이 자세는 등받이 0이 핵심이라 '정의 기반' 기준입니다.
A9: p3 | B9: cross_leg_right (오른다리 꼬기) | C9: 오른다리를 왼다리 위로 꼬고, 상체는 평소처럼 등받이에 기대세요. | D9: 오른쪽 비율이 낮아짐(관찰 36.2~43.5%, 4명 모두 46% 이하). 꼰 다리 쪽 엉덩이 하중이 줄어드는 것으로 보임. 뒤집은 방석 기준이므로 반대로 나오면 방석 좌우를 다시 확인. | E9: 등받이 접촉 유지(관찰 총압력 1,855~4,179). 등받이 좌우 비율은 사람마다 달라(23.6~58.8%) 기준 없음. | F9: =IF('합격 기준 수치표'!D9="","","• 방석 총압력 ≥ "&'합격 기준 수치표'!D9&" 원시값 합"&CHAR(10))&IF('합격 기준 수치표'!E9="","","• 방석 총압력 ≤ "&'합격 기준 수치표'!E9&" 원시값 합"&CHAR(10))&IF('합격 기준 수치표'!F9="","","• 등받이 총압력 ≥ "&'합격 기준 수치표'!F9&" 원시값 합"&CHAR(10))&IF('합격 기준 수치표'!G9="","","• 등받이 총압력 ≤ "&'합격 기준 수치표'!G9&" 원시값 합"&CHAR(10))&IF('합격 기준 수치표'!H9="","","• 엉덩이 줄 비중 ≥ "&'합격 기준 수치표'!H9&" %"&CHAR(10))&IF('합격 기준 수치표'!I9="","","• 엉덩이 줄 비중 ≤ "&'합격 기준 수치표'!I9&" %"&CHAR(10))&IF('합격 기준 수치표'!J9="","","• 방석 오른쪽 비율 ≥ "&'합격 기준 수치표'!J9&" %"&CHAR(10))&IF('합격 기준 수치표'!K9="","","• 방석 오른쪽 비율 ≤ "&'합격 기준 수치표'!K9&" %"&CHAR(10))&IF('합격 기준 수치표'!L9="","","• 등받이 오른쪽 비율 ≥ "&'합격 기준 수치표'!L9&" %"&CHAR(10))&IF('합격 기준 수치표'!M9="","","• 등받이 오른쪽 비율 ≤ "&'합격 기준 수치표'!M9&" %"&CHAR(10))&IF('합격 기준 수치표'!N9="","","• 등받이 어깨 줄 비중 ≥ "&'합격 기준 수치표'!N9&" %"&CHAR(10))&IF('합격 기준 수치표'!O9="","","• 등받이 어깨 줄 비중 ≤ "&'합격 기준 수치표'!O9&" %"&CHAR(10))&IF('합격 기준 수치표'!P9="","","• 등받이 반응 채널 수 ≥ "&'합격 기준 수치표'!P9&" 개"&CHAR(10))&IF('합격 기준 수치표'!Q9="","","• 등받이 반응 채널 수 ≤ "&'합격 기준 수치표'!Q9&" 개"&CHAR(10)) -> • 방석 총압력 ≥ 6000 원시값 합 • 등받이 총압력 ≥ 500 원시값 합 • 방석 오른쪽 비율 ≤ 46 % • 등받이 반응 채널 수 ≥ 4 개 | G9: 오른쪽 비율이 46%를 넘음 → 꼬기가 약한 것이니 다리를 확실히 꼬게 하고 재촬영. 오른다리·왼다리가 뒤바뀐 파일이 아닌지 확인(왼다리 꼬기 파일이 이 쪽에 들어갔는지).
A10: p4 | B10: cross_leg_left (왼다리 꼬기) | C10: 왼다리를 오른다리 위로 꼬고, 상체는 평소처럼 등받이에 기대세요. | D10: 오른쪽 비율이 높아짐(관찰 62.9~66.7%, 4명 모두 60% 이상). 오른다리 꼬기의 거울상. | E10: 등받이 접촉 유지(관찰 총압력 1,680~2,820). 등받이 좌우 비율은 사람마다 달라(0~78.2%) 기준 없음. | F10: =IF('합격 기준 수치표'!D10="","","• 방석 총압력 ≥ "&'합격 기준 수치표'!D10&" 원시값 합"&CHAR(10))&IF('합격 기준 수치표'!E10="","","• 방석 총압력 ≤ "&'합격 기준 수치표'!E10&" 원시값 합"&CHAR(10))&IF('합격 기준 수치표'!F10="","","• 등받이 총압력 ≥ "&'합격 기준 수치표'!F10&" 원시값 합"&CHAR(10))&IF('합격 기준 수치표'!G10="","","• 등받이 총압력 ≤ "&'합격 기준 수치표'!G10&" 원시값 합"&CHAR(10))&IF('합격 기준 수치표'!H10="","","• 엉덩이 줄 비중 ≥ "&'합격 기준 수치표'!H10&" %"&CHAR(10))&IF('합격 기준 수치표'!I10="","","• 엉덩이 줄 비중 ≤ "&'합격 기준 수치표'!I10&" %"&CHAR(10))&IF('합격 기준 수치표'!J10="","","• 방석 오른쪽 비율 ≥ "&'합격 기준 수치표'!J10&" %"&CHAR(10))&IF('합격 기준 수치표'!K10="","","• 방석 오른쪽 비율 ≤ "&'합격 기준 수치표'!K10&" %"&CHAR(10))&IF('합격 기준 수치표'!L10="","","• 등받이 오른쪽 비율 ≥ "&'합격 기준 수치표'!L10&" %"&CHAR(10))&IF('합격 기준 수치표'!M10="","","• 등받이 오른쪽 비율 ≤ "&'합격 기준 수치표'!M10&" %"&CHAR(10))&IF('합격 기준 수치표'!N10="","","• 등받이 어깨 줄 비중 ≥ "&'합격 기준 수치표'!N10&" %"&CHAR(10))&IF('합격 기준 수치표'!O10="","","• 등받이 어깨 줄 비중 ≤ "&'합격 기준 수치표'!O10&" %"&CHAR(10))&IF('합격 기준 수치표'!P10="","","• 등받이 반응 채널 수 ≥ "&'합격 기준 수치표'!P10&" 개"&CHAR(10))&IF('합격 기준 수치표'!Q10="","","• 등받이 반응 채널 수 ≤ "&'합격 기준 수치표'!Q10&" 개"&CHAR(10)) -> • 방석 총압력 ≥ 6000 원시값 합 • 등받이 총압력 ≥ 500 원시값 합 • 방석 오른쪽 비율 ≥ 60 % • 등받이 반응 채널 수 ≥ 4 개 | G10: 오른쪽 비율이 60% 미만 → 꼬기가 약하거나 왼·오른 파일이 뒤바뀐 것. 확인 후 재촬영.
A11: p5 | B11: lean_right (오른쪽 기대기) | C11: 상체를 오른쪽 팔걸이 쪽으로 기대세요. 몸 전체가 오른쪽으로 쏠리게 해 주세요. | D11: 오른쪽 비율 증가(관찰 56.2~69.3%, 하한 52%). 사람에 따라 약할 수 있음(yewon 56.2%). | E11: 등받이 오른쪽에 쏠림. 오른쪽 비율 80% 이상(관찰 90.1~100%). 이 지표가 방석보다 훨씬 뚜렷해서 핵심 기준. | F11: =IF('합격 기준 수치표'!D11="","","• 방석 총압력 ≥ "&'합격 기준 수치표'!D11&" 원시값 합"&CHAR(10))&IF('합격 기준 수치표'!E11="","","• 방석 총압력 ≤ "&'합격 기준 수치표'!E11&" 원시값 합"&CHAR(10))&IF('합격 기준 수치표'!F11="","","• 등받이 총압력 ≥ "&'합격 기준 수치표'!F11&" 원시값 합"&CHAR(10))&IF('합격 기준 수치표'!G11="","","• 등받이 총압력 ≤ "&'합격 기준 수치표'!G11&" 원시값 합"&CHAR(10))&IF('합격 기준 수치표'!H11="","","• 엉덩이 줄 비중 ≥ "&'합격 기준 수치표'!H11&" %"&CHAR(10))&IF('합격 기준 수치표'!I11="","","• 엉덩이 줄 비중 ≤ "&'합격 기준 수치표'!I11&" %"&CHAR(10))&IF('합격 기준 수치표'!J11="","","• 방석 오른쪽 비율 ≥ "&'합격 기준 수치표'!J11&" %"&CHAR(10))&IF('합격 기준 수치표'!K11="","","• 방석 오른쪽 비율 ≤ "&'합격 기준 수치표'!K11&" %"&CHAR(10))&IF('합격 기준 수치표'!L11="","","• 등받이 오른쪽 비율 ≥ "&'합격 기준 수치표'!L11&" %"&CHAR(10))&IF('합격 기준 수치표'!M11="","","• 등받이 오른쪽 비율 ≤ "&'합격 기준 수치표'!M11&" %"&CHAR(10))&IF('합격 기준 수치표'!N11="","","• 등받이 어깨 줄 비중 ≥ "&'합격 기준 수치표'!N11&" %"&CHAR(10))&IF('합격 기준 수치표'!O11="","","• 등받이 어깨 줄 비중 ≤ "&'합격 기준 수치표'!O11&" %"&CHAR(10))&IF('합격 기준 수치표'!P11="","","• 등받이 반응 채널 수 ≥ "&'합격 기준 수치표'!P11&" 개"&CHAR(10))&IF('합격 기준 수치표'!Q11="","","• 등받이 반응 채널 수 ≤ "&'합격 기준 수치표'!Q11&" 개"&CHAR(10)) -> • 방석 총압력 ≥ 6000 원시값 합 • 등받이 총압력 ≥ 1000 원시값 합 • 방석 오른쪽 비율 ≥ 52 % • 등받이 오른쪽 비율 ≥ 80 % • 등받이 반응 채널 수 ≥ 4 개 | G11: 등받이 오른쪽 비율이 80% 미만 → 덜 기댄 것이니 재촬영. 왼쪽으로 나오면 왼쪽 기대기와 바뀐 파일이거나 등받이 좌우(뒤집은 방향) 설정 문제.
A12: p6 | B12: lean_left (왼쪽 기대기) | C12: 상체를 왼쪽 팔걸이 쪽으로 기대세요. 몸 전체가 왼쪽으로 쏠리게 해 주세요. | D12: 방석에는 뚜렷한 쏠림이 없음(관찰 오른쪽 비율 44.4~55.0%) → 방석 좌우 기준을 두지 않음. 오른쪽 기대기와 달리 방석만으로는 구분이 어렵다는 뜻. | E12: 등받이 왼쪽에 쏠림. 오른쪽 비율 20% 이하(관찰 0~10.8%). 핵심 기준. | F12: =IF('합격 기준 수치표'!D12="","","• 방석 총압력 ≥ "&'합격 기준 수치표'!D12&" 원시값 합"&CHAR(10))&IF('합격 기준 수치표'!E12="","","• 방석 총압력 ≤ "&'합격 기준 수치표'!E12&" 원시값 합"&CHAR(10))&IF('합격 기준 수치표'!F12="","","• 등받이 총압력 ≥ "&'합격 기준 수치표'!F12&" 원시값 합"&CHAR(10))&IF('합격 기준 수치표'!G12="","","• 등받이 총압력 ≤ "&'합격 기준 수치표'!G12&" 원시값 합"&CHAR(10))&IF('합격 기준 수치표'!H12="","","• 엉덩이 줄 비중 ≥ "&'합격 기준 수치표'!H12&" %"&CHAR(10))&IF('합격 기준 수치표'!I12="","","• 엉덩이 줄 비중 ≤ "&'합격 기준 수치표'!I12&" %"&CHAR(10))&IF('합격 기준 수치표'!J12="","","• 방석 오른쪽 비율 ≥ "&'합격 기준 수치표'!J12&" %"&CHAR(10))&IF('합격 기준 수치표'!K12="","","• 방석 오른쪽 비율 ≤ "&'합격 기준 수치표'!K12&" %"&CHAR(10))&IF('합격 기준 수치표'!L12="","","• 등받이 오른쪽 비율 ≥ "&'합격 기준 수치표'!L12&" %"&CHAR(10))&IF('합격 기준 수치표'!M12="","","• 등받이 오른쪽 비율 ≤ "&'합격 기준 수치표'!M12&" %"&CHAR(10))&IF('합격 기준 수치표'!N12="","","• 등받이 어깨 줄 비중 ≥ "&'합격 기준 수치표'!N12&" %"&CHAR(10))&IF('합격 기준 수치표'!O12="","","• 등받이 어깨 줄 비중 ≤ "&'합격 기준 수치표'!O12&" %"&CHAR(10))&IF('합격 기준 수치표'!P12="","","• 등받이 반응 채널 수 ≥ "&'합격 기준 수치표'!P12&" 개"&CHAR(10))&IF('합격 기준 수치표'!Q12="","","• 등받이 반응 채널 수 ≤ "&'합격 기준 수치표'!Q12&" 개"&CHAR(10)) -> • 방석 총압력 ≥ 6000 원시값 합 • 등받이 총압력 ≥ 1000 원시값 합 • 등받이 오른쪽 비율 ≤ 20 % • 등받이 반응 채널 수 ≥ 4 개 | G12: 등받이 오른쪽 비율이 20%를 넘음 → 덜 기댄 것이니 재촬영. 방석이 균형이어도 불합격 사유가 아님.
A13: p7 | B13: turtle_neck (거북목) | C13: 등은 등받이에 댄 채, 어깨 부분은 등받이에서 띄우세요. 그 상태에서 머리와 목을 앞으로 내미세요. | D13: 정자세와 비슷(오른쪽 비율 40~60%, 관찰 50.3~55.7%). 엉덩이 비중은 정자세와 겹쳐 기준 없음. | E13: 등(허리·중간 줄)은 닿고 어깨 줄은 거의 0(관찰 어깨 줄 0~0.4%, 기준 3% 이하). 등 접촉은 정자세보다 약해짐(같은 사람 정자세 대비 관찰 0.5~72%). | F13: =IF('합격 기준 수치표'!D13="","","• 방석 총압력 ≥ "&'합격 기준 수치표'!D13&" 원시값 합"&CHAR(10))&IF('합격 기준 수치표'!E13="","","• 방석 총압력 ≤ "&'합격 기준 수치표'!E13&" 원시값 합"&CHAR(10))&IF('합격 기준 수치표'!F13="","","• 등받이 총압력 ≥ "&'합격 기준 수치표'!F13&" 원시값 합"&CHAR(10))&IF('합격 기준 수치표'!G13="","","• 등받이 총압력 ≤ "&'합격 기준 수치표'!G13&" 원시값 합"&CHAR(10))&IF('합격 기준 수치표'!H13="","","• 엉덩이 줄 비중 ≥ "&'합격 기준 수치표'!H13&" %"&CHAR(10))&IF('합격 기준 수치표'!I13="","","• 엉덩이 줄 비중 ≤ "&'합격 기준 수치표'!I13&" %"&CHAR(10))&IF('합격 기준 수치표'!J13="","","• 방석 오른쪽 비율 ≥ "&'합격 기준 수치표'!J13&" %"&CHAR(10))&IF('합격 기준 수치표'!K13="","","• 방석 오른쪽 비율 ≤ "&'합격 기준 수치표'!K13&" %"&CHAR(10))&IF('합격 기준 수치표'!L13="","","• 등받이 오른쪽 비율 ≥ "&'합격 기준 수치표'!L13&" %"&CHAR(10))&IF('합격 기준 수치표'!M13="","","• 등받이 오른쪽 비율 ≤ "&'합격 기준 수치표'!M13&" %"&CHAR(10))&IF('합격 기준 수치표'!N13="","","• 등받이 어깨 줄 비중 ≥ "&'합격 기준 수치표'!N13&" %"&CHAR(10))&IF('합격 기준 수치표'!O13="","","• 등받이 어깨 줄 비중 ≤ "&'합격 기준 수치표'!O13&" %"&CHAR(10))&IF('합격 기준 수치표'!P13="","","• 등받이 반응 채널 수 ≥ "&'합격 기준 수치표'!P13&" 개"&CHAR(10))&IF('합격 기준 수치표'!Q13="","","• 등받이 반응 채널 수 ≤ "&'합격 기준 수치표'!Q13&" 개"&CHAR(10)) -> • 방석 총압력 ≥ 6000 원시값 합 • 등받이 총압력 ≥ 400 원시값 합 • 방석 오른쪽 비율 ≥ 40 % • 방석 오른쪽 비율 ≤ 60 % • 등받이 어깨 줄 비중 ≤ 3 % • 등받이 반응 채널 수 ≥ 3 개 | G13: 등받이 총압력이 400 미만 → 등이 등받이에 닿지 않은 것(앞으로 숙이기와 구분 안 됨). 관찰: aro 236, junseo 7이 여기에 해당 → 재촬영. 어깨 줄이 3%를 넘으면 어깨가 닿은 것이니 어깨를 더 띄우게 하고 재촬영. 정자세도 어깨 줄이 0인 사람이 많아 어깨 줄 하나로는 정자세와 안 갈리니, 같은 사람의 정자세 파일과 함께 비교.
A16: 공통 품질 기준 (모든 자세·모든 파일)
B17: 항목 | C17: 기준 (수치표 연동) | D17: 이유 | E17: 확인 방법
B18: 수집 길이 | C18: ="길이 "&'합격 기준 수치표'!D18&"~"&'합격 기준 수치표'!D19&"초, 프레임 "&'합격 기준 수치표'!D17&" 이상" -> 길이 19~22초, 프레임 1100 이상 | D18: 자세당 20초 수집이 기본. 짧거나 프레임이 적으면 수신이 끊긴 것 | E18: 수집 현황의 '품질' 열
B19: 수신 속도 | C19: ="fps "&'합격 기준 수치표'!D20&"~"&'합격 기준 수치표'!D21 -> fps 55~70 | D19: 두 보드 동시 수집이 정상이면 일정하게 나옴(관찰 62.3) | E19: 수집 현황의 '품질' 열
B20: 자세 중 움직임 | C20: ="방석 흔들림(CV) ≤ "&'합격 기준 수치표'!D22&"%" -> 방석 흔들림(CV) ≤ 10% | D20: 자세를 유지하지 못하면 라벨이 섞임. 관찰 0.2~17.6, aro 2개 파일(lean_right 16.4, turtle_neck 17.6)이 초과 | E20: 수집 현황의 '방석 흔들림' 열
B21: 센서 포화 | C21: ="포화 비율 ≤ "&'합격 기준 수치표'!D23&"%" -> 포화 비율 ≤ 0.5% | D21: 최댓값에 붙으면 압력 차이가 사라짐(체격이 큰 참가자에서 확인) | E21: 수집 현황의 '포화 비율' 열
B22: 빈 의자 판단 | C22: ="방석 총압력 ≤ "&'합격 기준 수치표'!D24&" 이면 앉지 않음으로 간주" -> 방석 총압력 ≤ 300 이면 앉지 않음으로 간주 | D22: 앉지 않음 파일은 움직임 검사에서 제외하기 위한 기준 | E22: 수치표 하단
A24: 참가자 단위 기준 (사람마다)
B25: 항목 | C25: 기준 | D25: 이유
B26: 자세 종류 | C26: 8자세 모두, 자세당 목표 회차 이상 합격 파일 | D26: 한 자세라도 없으면 그 사람의 데이터를 학습·평가에 쓰기 어려움 ('자세 수집 현황' 시트)
B27: 자세 순서 | C27: 참가자마다 순서를 섞어서 수집 | D27: 순서 효과(앞 자세의 피로·자세 습관)가 특정 자세에 몰리지 않게
B28: 자세 사이 | C28: 자세마다 일어났다가 다시 앉고 카운트다운 후 시작 | D28: 앞 자세의 압력 흔적과 앉는 위치 고정을 없애기 위해
B29: 의자 조건 | C29: 의자 높이·등받이 각도·매트 위치를 참가자 간 같게 유지하고 기록 | D29: 참가자 차이와 설치 차이를 섞지 않기 위해 (E15는 일부러 바꾸는 케이스)
B30: 옷·소지품 | C30: 겉옷 두께와 뒷주머니·가방 여부를 기록 | D30: 등받이·방석 압력을 바꾸는 요인 (E13에서 일부러 비교)
B31: 좌우 확인 | C31: 수집 첫날 탭 테스트로 방석·등받이 좌우와 어깨 줄 위치를 확인 | D31: 매트를 뒤집었기 때문에 번호와 좌우의 대응을 데이터와 맞춰야 함
B32: 파일 이름 | C32: person은 영문 소문자, 같은 사람은 항상 같은 이름 | D32: 학습 때 사람 단위로 나누려면 이름이 일관돼야 함
B33: 불합격 파일 | C33: 삭제하지 말고 파일명에 _reject를 붙여 따로 보관 | D33: 변환 스크립트가 _reject 파일을 건너뛰고, 나중에 기준을 바꿔 다시 볼 수 있음
B34: 평가 방식 | C34: 학습은 일부 사람, 평가는 다른 사람으로 분리 (--holdout-persons) | D34: 같은 사람의 프레임이 학습과 평가에 섞이면 점수가 부풀려짐

Sheet 합격 기준 수치표
A1: 자세별 합격 기준 — 수치표
A2: '수집 현황' 시트의 합격/불합격 판정이 이 표를 읽습니다. 파란 숫자를 바꾸면 판정이 바로 바뀝니다. 빈칸 = 그 지표는 이 자세의 기준이 아님.
A3: 초안입니다. 2026-10-18 실측 4명 28파일(자세당 2~4개)에서 정했으므로 참가자가 늘면 '실측 관찰값' 시트를 보며 다시 조정하세요.
D4: 방석 총압력 (원시값 합) | F4: 등받이 총압력 (원시값 합) | H4: 엉덩이 줄 비중 (%) | J4: 방석 오른쪽 비율 (%) | L4: 등받이 오른쪽 비율 (%) | N4: 등받이 어깨 줄 비중 (%) | P4: 등받이 반응 채널 수 (개)
A5: 코드 | B5: 자세 (영문) | C5: 자세 (한글) | D5: 하한 (이상) | E5: 상한 (이하) | F5: 하한 (이상) | G5: 상한 (이하) | H5: 하한 (이상) | I5: 상한 (이하) | J5: 하한 (이상) | K5: 상한 (이하) | L5: 하한 (이상) | M5: 상한 (이하) | N5: 하한 (이상) | O5: 상한 (이하) | P5: 하한 (이상) | Q5: 상한 (이하)
A6: p0 | B6: not_sitting | C6: 앉지 않음 | E6: 300 | G6: 100
A7: p1 | B7: sitting_straight | C7: 정자세 | D7: 6000 | F7: 1000 | J7: 40 | K7: 60 | P7: 4
A8: p2 | B8: lean_forward | C8: 앞으로 숙이기 | D8: 6000 | G8: 100 | I8: 32 | J8: 40 | K8: 60
A9: p3 | B9: cross_leg_right | C9: 오른다리 꼬기 | D9: 6000 | F9: 500 | K9: 46 | P9: 4
A10: p4 | B10: cross_leg_left | C10: 왼다리 꼬기 | D10: 6000 | F10: 500 | J10: 60 | P10: 4
A11: p5 | B11: lean_right | C11: 오른쪽 기대기 | D11: 6000 | F11: 1000 | J11: 52 | L11: 80 | P11: 4
A12: p6 | B12: lean_left | C12: 왼쪽 기대기 | D12: 6000 | F12: 1000 | M12: 20 | P12: 4
A13: p7 | B13: turtle_neck | C13: 거북목 | D13: 6000 | F13: 400 | J13: 40 | K13: 60 | O13: 3 | P13: 3
A15: 공통 품질 기준 (모든 자세에 적용)
A16: 항목 | D16: 값 | E16: 설명
A17: 최소 프레임 수 | D17: 1100 | E17: 20초 × 약 62fps ≈ 1,240프레임. 이보다 적으면 수신이 끊긴 것
A18: 길이 하한 (초) | D18: 19 | E18: 자세당 20초 수집이 기본
A19: 길이 상한 (초) | D19: 22
A20: fps 하한 | D20: 55 | E20: 관찰값 62.3 (모든 파일 동일)
A21: fps 상한 | D21: 70
A22: 방석 흔들림 상한 (CV %) | D22: 10 | E22: 프레임별 방석 총압력의 변동계수. 크면 자세 중 몸을 움직인 것 (관찰 0.2~17.6)
A23: 포화 비율 상한 (%) | D23: 0.5 | E23: 전체 샘플 중 최댓값 근처(1,043 이상)에 붙은 비율. 관찰 최대 0.018
A24: 빈 의자로 볼 방석 총압력 | D24: 300 | E24: 이 값 이하면 앉지 않은 것으로 보고 흔들림 검사를 건너뜀
A26: 기준을 정한 근거: '정의 기반'(자세 정의상 반드시 그래야 함: 앞으로 숙이기의 등받이 0, 거북목의 어깨 줄 0 등)과 '관찰 기반'(실측 분포에서 여유를 두고 정함)이 섞여 있습니다. 항목별 관찰 범위는 '실측 관찰값' 시트에 있습니다.

Sheet 수집 현황
A1: 수집 현황 · 자동 판정
A2: A~P열: qc_64ch.py 결과를 A6부터 붙여 넣으세요(파란 글씨 = 입력값). Q~AA열은 자동 판정입니다. 100행(6~105)까지 수식이 준비돼 있습니다.
A3: 판정: OK=기준 충족, X=기준 미달, N/A=지표를 계산할 수 없음(등받이 접촉이 거의 없어 비율을 못 구함), -=이 자세의 기준 아님. 종합 PASS = 품질 OK이고 X가 하나도 없음.
A5: 파일명 | B5: person | C5: 자세 | D5: 회차 | E5: 프레임 수 | F5: 길이(초) | G5: fps | H5: 방석 총압력 | I5: 등받이 총압력 | J5: 엉덩이 줄 비중(%) | K5: 방석 오른쪽(%) | L5: 등받이 오른쪽(%) | M5: 등받이 어깨 줄(%) | N5: 등받이 반응 채널 수 | O5: 방석 흔들림(CV%) | P5: 포화 비율(%) | Q5: 기준 행 | R5: 품질 | S5: 방석 총압력 | T5: 등받이 총압력 | U5: 엉덩이 줄 비중 | V5: 방석 오른쪽 비율 | W5: 등받이 오른쪽 비율 | X5: 등받이 어깨 줄 비중 | Y5: 등받이 반응 채널 수 | Z5: 실패 수 | AA5: 종합
A6: aro_cross_leg_left_1.csv | B6: aro | C6: cross_leg_left | D6: 1 | E6: 1245 | F6: 20 | G6: 62.3 | H6: 12081 | I6: 1757 | J6: 56.6 | K6: 63.9 | L6: 55 | M6: 0 | N6: 12 | O6: 1.1 | P6: 0 | Q6: =IF($A6="","",IFERROR(MATCH($C6,'합격 기준 수치표'!$B$6:$B$13,0),0)) -> 5 | R6: =IF($A6="","",IF(AND(E6>='합격 기준 수치표'!$D$17,F6>='합격 기준 수치표'!$D$18,F6<='합격 기준 수치표'!$D$19,G6>='합격 기준 수치표'!$D$20,G6<='합격 기준 수치표'!$D$21,P6<='합격 기준 수치표'!$D$23,OR(H6<='합격 기준 수치표'!$D$24,O6="",O6<='합격 기준 수치표'!$D$22)),"OK","X")) -> OK | S6: =IF($A6="","",IF($Q6=0,"?",IF(AND(INDEX('합격 기준 수치표'!$D$6:$D$13,$Q6)="",INDEX('합격 기준 수치표'!$E$6:$E$13,$Q6)=""),"-",IF(H6="","N/A",IF(OR(AND(INDEX('합격 기준 수치표'!$D$6:$D$13,$Q6)<>"",H6<INDEX('합격 기준 수치표'!$D$6:$D$13,$Q6)),AND(INDEX('합격 기준 수치표'!$E$6:$E$13,$Q6)<>"",H6>INDEX('합격 기준 수치표'!$E$6:$E$13,$Q6))),"X","OK"))))) -> OK | T6: =IF($A6="","",IF($Q6=0,"?",IF(AND(INDEX('합격 기준 수치표'!$F$6:$F$13,$Q6)="",INDEX('합격 기준 수치표'!$G$6:$G$13,$Q6)=""),"-",IF(I6="","N/A",IF(OR(AND(INDEX('합격 기준 수치표'!$F$6:$F$13,$Q6)<>"",I6<INDEX('합격 기준 수치표'!$F$6:$F$13,$Q6)),AND(INDEX('합격 기준 수치표'!$G$6:$G$13,$Q6)<>"",I6>INDEX('합격 기준 수치표'!$G$6:$G$13,$Q6))),"X","OK"))))) -> OK | U6: =IF($A6="","",IF($Q6=0,"?",IF(AND(INDEX('합격 기준 수치표'!$H$6:$H$13,$Q6)="",INDEX('합격 기준 수치표'!$I$6:$I$13,$Q6)=""),"-",IF(J6="","N/A",IF(OR(AND(INDEX('합격 기준 수치표'!$H$6:$H$13,$Q6)<>"",J6<INDEX('합격 기준 수치표'!$H$6:$H$13,$Q6)),AND(INDEX('합격 기준 수치표'!$I$6:$I$13,$Q6)<>"",J6>INDEX('합격 기준 수치표'!$I$6:$I$13,$Q6))),"X","OK"))))) -> - | V6: =IF($A6="","",IF($Q6=0,"?",IF(AND(INDEX('합격 기준 수치표'!$J$6:$J$13,$Q6)="",INDEX('합격 기준 수치표'!$K$6:$K$13,$Q6)=""),"-",IF(K6="","N/A",IF(OR(AND(INDEX('합격 기준 수치표'!$J$6:$J$13,$Q6)<>"",K6<INDEX('합격 기준 수치표'!$J$6:$J$13,$Q6)),AND(INDEX('합격 기준 수치표'!$K$6:$K$13,$Q6)<>"",K6>INDEX('합격 기준 수치표'!$K$6:$K$13,$Q6))),"X","OK"))))) -> OK | W6: =IF($A6="","",IF($Q6=0,"?",IF(AND(INDEX('합격 기준 수치표'!$L$6:$L$13,$Q6)="",INDEX('합격 기준 수치표'!$M$6:$M$13,$Q6)=""),"-",IF(L6="","N/A",IF(OR(AND(INDEX('합격 기준 수치표'!$L$6:$L$13,$Q6)<>"",L6<INDEX('합격 기준 수치표'!$L$6:$L$13,$Q6)),AND(INDEX('합격 기준 수치표'!$M$6:$M$13,$Q6)<>"",L6>INDEX('합격 기준 수치표'!$M$6:$M$13,$Q6))),"X","OK"))))) -> - | X6: =IF($A6="","",IF($Q6=0,"?",IF(AND(INDEX('합격 기준 수치표'!$N$6:$N$13,$Q6)="",INDEX('합격 기준 수치표'!$O$6:$O$13,$Q6)=""),"-",IF(M6="","N/A",IF(OR(AND(INDEX('합격 기준 수치표'!$N$6:$N$13,$Q6)<>"",M6<INDEX('합격 기준 수치표'!$N$6:$N$13,$Q6)),AND(INDEX('합격 기준 수치표'!$O$6:$O$13,$Q6)<>"",M6>INDEX('합격 기준 수치표'!$O$6:$O$13,$Q6))),"X","OK"))))) -> - | Y6: =IF($A6="","",IF($Q6=0,"?",IF(AND(INDEX('합격 기준 수치표'!$P$6:$P$13,$Q6)="",INDEX('합격 기준 수치표'!$Q$6:$Q$13,$Q6)=""),"-",IF(N6="","N/A",IF(OR(AND(INDEX('합격 기준 수치표'!$P$6:$P$13,$Q6)<>"",N6<INDEX('합격 기준 수치표'!$P$6:$P$13,$Q6)),AND(INDEX('합격 기준 수치표'!$Q$6:$Q$13,$Q6)<>"",N6>INDEX('합격 기준 수치표'!$Q$6:$Q$13,$Q6))),"X","OK"))))) -> OK | Z6: =IF($A6="","",COUNTIF($S6:$Y6,"X")+IF($R6="X",1,0)) -> 0 | AA6: =IF($A6="","",IF($Q6=0,"자세명 확인",IF($Z6=0,"PASS","FAIL"))) -> PASS
A7: aro_cross_leg_right_1.csv | B7: aro | C7: cross_leg_right | D7: 1 | E7: 1244 | F7: 20 | G7: 62.3 | H7: 10586 | I7: 2782 | J7: 61.4 | K7: 39.2 | L7: 41.8 | M7: 0 | N7: 14 | O7: 5.8 | P7: 0 | Q7: =IF($A7="","",IFERROR(MATCH($C7,'합격 기준 수치표'!$B$6:$B$13,0),0)) -> 4 | R7: =IF($A7="","",IF(AND(E7>='합격 기준 수치표'!$D$17,F7>='합격 기준 수치표'!$D$18,F7<='합격 기준 수치표'!$D$19,G7>='합격 기준 수치표'!$D$20,G7<='합격 기준 수치표'!$D$21,P7<='합격 기준 수치표'!$D$23,OR(H7<='합격 기준 수치표'!$D$24,O7="",O7<='합격 기준 수치표'!$D$22)),"OK","X")) -> OK | S7: =IF($A7="","",IF($Q7=0,"?",IF(AND(INDEX('합격 기준 수치표'!$D$6:$D$13,$Q7)="",INDEX('합격 기준 수치표'!$E$6:$E$13,$Q7)=""),"-",IF(H7="","N/A",IF(OR(AND(INDEX('합격 기준 수치표'!$D$6:$D$13,$Q7)<>"",H7<INDEX('합격 기준 수치표'!$D$6:$D$13,$Q7)),AND(INDEX('합격 기준 수치표'!$E$6:$E$13,$Q7)<>"",H7>INDEX('합격 기준 수치표'!$E$6:$E$13,$Q7))),"X","OK"))))) -> OK | T7: =IF($A7="","",IF($Q7=0,"?",IF(AND(INDEX('합격 기준 수치표'!$F$6:$F$13,$Q7)="",INDEX('합격 기준 수치표'!$G$6:$G$13,$Q7)=""),"-",IF(I7="","N/A",IF(OR(AND(INDEX('합격 기준 수치표'!$F$6:$F$13,$Q7)<>"",I7<INDEX('합격 기준 수치표'!$F$6:$F$13,$Q7)),AND(INDEX('합격 기준 수치표'!$G$6:$G$13,$Q7)<>"",I7>INDEX('합격 기준 수치표'!$G$6:$G$13,$Q7))),"X","OK"))))) -> OK | U7: =IF($A7="","",IF($Q7=0,"?",IF(AND(INDEX('합격 기준 수치표'!$H$6:$H$13,$Q7)="",INDEX('합격 기준 수치표'!$I$6:$I$13,$Q7)=""),"-",IF(J7="","N/A",IF(OR(AND(INDEX('합격 기준 수치표'!$H$6:$H$13,$Q7)<>"",J7<INDEX('합격 기준 수치표'!$H$6:$H$13,$Q7)),AND(INDEX('합격 기준 수치표'!$I$6:$I$13,$Q7)<>"",J7>INDEX('합격 기준 수치표'!$I$6:$I$13,$Q7))),"X","OK"))))) -> - | V7: =IF($A7="","",IF($Q7=0,"?",IF(AND(INDEX('합격 기준 수치표'!$J$6:$J$13,$Q7)="",INDEX('합격 기준 수치표'!$K$6:$K$13,$Q7)=""),"-",IF(K7="","N/A",IF(OR(AND(INDEX('합격 기준 수치표'!$J$6:$J$13,$Q7)<>"",K7<INDEX('합격 기준 수치표'!$J$6:$J$13,$Q7)),AND(INDEX('합격 기준 수치표'!$K$6:$K$13,$Q7)<>"",K7>INDEX('합격 기준 수치표'!$K$6:$K$13,$Q7))),"X","OK"))))) -> OK | W7: =IF($A7="","",IF($Q7=0,"?",IF(AND(INDEX('합격 기준 수치표'!$L$6:$L$13,$Q7)="",INDEX('합격 기준 수치표'!$M$6:$M$13,$Q7)=""),"-",IF(L7="","N/A",IF(OR(AND(INDEX('합격 기준 수치표'!$L$6:$L$13,$Q7)<>"",L7<INDEX('합격 기준 수치표'!$L$6:$L$13,$Q7)),AND(INDEX('합격 기준 수치표'!$M$6:$M$13,$Q7)<>"",L7>INDEX('합격 기준 수치표'!$M$6:$M$13,$Q7))),"X","OK"))))) -> - | X7: =IF($A7="","",IF($Q7=0,"?",IF(AND(INDEX('합격 기준 수치표'!$N$6:$N$13,$Q7)="",INDEX('합격 기준 수치표'!$O$6:$O$13,$Q7)=""),"-",IF(M7="","N/A",IF(OR(AND(INDEX('합격 기준 수치표'!$N$6:$N$13,$Q7)<>"",M7<INDEX('합격 기준 수치표'!$N$6:$N$13,$Q7)),AND(INDEX('합격 기준 수치표'!$O$6:$O$13,$Q7)<>"",M7>INDEX('합격 기준 수치표'!$O$6:$O$13,$Q7))),"X","OK"))))) -> - | Y7: =IF($A7="","",IF($Q7=0,"?",IF(AND(INDEX('합격 기준 수치표'!$P$6:$P$13,$Q7)="",INDEX('합격 기준 수치표'!$Q$6:$Q$13,$Q7)=""),"-",IF(N7="","N/A",IF(OR(AND(INDEX('합격 기준 수치표'!$P$6:$P$13,$Q7)<>"",N7<INDEX('합격 기준 수치표'!$P$6:$P$13,$Q7)),AND(INDEX('합격 기준 수치표'!$Q$6:$Q$13,$Q7)<>"",N7>INDEX('합격 기준 수치표'!$Q$6:$Q$13,$Q7))),"X","OK"))))) -> OK | Z7: =IF($A7="","",COUNTIF($S7:$Y7,"X")+IF($R7="X",1,0)) -> 0 | AA7: =IF($A7="","",IF($Q7=0,"자세명 확인",IF($Z7=0,"PASS","FAIL"))) -> PASS
A8: aro_lean_right_1.csv | B8: aro | C8: lean_right | D8: 1 | E8: 1245 | F8: 20 | G8: 62.3 | H8: 9694 | I8: 1890 | J8: 51.7 | K8: 68.9 | L8: 90.1 | M8: 0.7 | N8: 12 | O8: 16.4 | P8: 0 | Q8: =IF($A8="","",IFERROR(MATCH($C8,'합격 기준 수치표'!$B$6:$B$13,0),0)) -> 6 | R8: =IF($A8="","",IF(AND(E8>='합격 기준 수치표'!$D$17,F8>='합격 기준 수치표'!$D$18,F8<='합격 기준 수치표'!$D$19,G8>='합격 기준 수치표'!$D$20,G8<='합격 기준 수치표'!$D$21,P8<='합격 기준 수치표'!$D$23,OR(H8<='합격 기준 수치표'!$D$24,O8="",O8<='합격 기준 수치표'!$D$22)),"OK","X")) -> X | S8: =IF($A8="","",IF($Q8=0,"?",IF(AND(INDEX('합격 기준 수치표'!$D$6:$D$13,$Q8)="",INDEX('합격 기준 수치표'!$E$6:$E$13,$Q8)=""),"-",IF(H8="","N/A",IF(OR(AND(INDEX('합격 기준 수치표'!$D$6:$D$13,$Q8)<>"",H8<INDEX('합격 기준 수치표'!$D$6:$D$13,$Q8)),AND(INDEX('합격 기준 수치표'!$E$6:$E$13,$Q8)<>"",H8>INDEX('합격 기준 수치표'!$E$6:$E$13,$Q8))),"X","OK"))))) -> OK | T8: =IF($A8="","",IF($Q8=0,"?",IF(AND(INDEX('합격 기준 수치표'!$F$6:$F$13,$Q8)="",INDEX('합격 기준 수치표'!$G$6:$G$13,$Q8)=""),"-",IF(I8="","N/A",IF(OR(AND(INDEX('합격 기준 수치표'!$F$6:$F$13,$Q8)<>"",I8<INDEX('합격 기준 수치표'!$F$6:$F$13,$Q8)),AND(INDEX('합격 기준 수치표'!$G$6:$G$13,$Q8)<>"",I8>INDEX('합격 기준 수치표'!$G$6:$G$13,$Q8))),"X","OK"))))) -> OK | U8: =IF($A8="","",IF($Q8=0,"?",IF(AND(INDEX('합격 기준 수치표'!$H$6:$H$13,$Q8)="",INDEX('합격 기준 수치표'!$I$6:$I$13,$Q8)=""),"-",IF(J8="","N/A",IF(OR(AND(INDEX('합격 기준 수치표'!$H$6:$H$13,$Q8)<>"",J8<INDEX('합격 기준 수치표'!$H$6:$H$13,$Q8)),AND(INDEX('합격 기준 수치표'!$I$6:$I$13,$Q8)<>"",J8>INDEX('합격 기준 수치표'!$I$6:$I$13,$Q8))),"X","OK"))))) -> - | V8: =IF($A8="","",IF($Q8=0,"?",IF(AND(INDEX('합격 기준 수치표'!$J$6:$J$13,$Q8)="",INDEX('합격 기준 수치표'!$K$6:$K$13,$Q8)=""),"-",IF(K8="","N/A",IF(OR(AND(INDEX('합격 기준 수치표'!$J$6:$J$13,$Q8)<>"",K8<INDEX('합격 기준 수치표'!$J$6:$J$13,$Q8)),AND(INDEX('합격 기준 수치표'!$K$6:$K$13,$Q8)<>"",K8>INDEX('합격 기준 수치표'!$K$6:$K$13,$Q8))),"X","OK"))))) -> OK | W8: =IF($A8="","",IF($Q8=0,"?",IF(AND(INDEX('합격 기준 수치표'!$L$6:$L$13,$Q8)="",INDEX('합격 기준 수치표'!$M$6:$M$13,$Q8)=""),"-",IF(L8="","N/A",IF(OR(AND(INDEX('합격 기준 수치표'!$L$6:$L$13,$Q8)<>"",L8<INDEX('합격 기준 수치표'!$L$6:$L$13,$Q8)),AND(INDEX('합격 기준 수치표'!$M$6:$M$13,$Q8)<>"",L8>INDEX('합격 기준 수치표'!$M$6:$M$13,$Q8))),"X","OK"))))) -> OK | X8: =IF($A8="","",IF($Q8=0,"?",IF(AND(INDEX('합격 기준 수치표'!$N$6:$N$13,$Q8)="",INDEX('합격 기준 수치표'!$O$6:$O$13,$Q8)=""),"-",IF(M8="","N/A",IF(OR(AND(INDEX('합격 기준 수치표'!$N$6:$N$13,$Q8)<>"",M8<INDEX('합격 기준 수치표'!$N$6:$N$13,$Q8)),AND(INDEX('합격 기준 수치표'!$O$6:$O$13,$Q8)<>"",M8>INDEX('합격 기준 수치표'!$O$6:$O$13,$Q8))),"X","OK"))))) -> - | Y8: =IF($A8="","",IF($Q8=0,"?",IF(AND(INDEX('합격 기준 수치표'!$P$6:$P$13,$Q8)="",INDEX('합격 기준 수치표'!$Q$6:$Q$13,$Q8)=""),"-",IF(N8="","N/A",IF(OR(AND(INDEX('합격 기준 수치표'!$P$6:$P$13,$Q8)<>"",N8<INDEX('합격 기준 수치표'!$P$6:$P$13,$Q8)),AND(INDEX('합격 기준 수치표'!$Q$6:$Q$13,$Q8)<>"",N8>INDEX('합격 기준 수치표'!$Q$6:$Q$13,$Q8))),"X","OK"))))) -> OK | Z8: =IF($A8="","",COUNTIF($S8:$Y8,"X")+IF($R8="X",1,0)) -> 1 | AA8: =IF($A8="","",IF($Q8=0,"자세명 확인",IF($Z8=0,"PASS","FAIL"))) -> FAIL
A9: aro_sitting_straight_2.csv | B9: aro | C9: sitting_straight | D9: 2 | E9: 1245 | F9: 20 | G9: 62.3 | H9: 12273 | I9: 4050 | J9: 51.3 | K9: 49.2 | L9: 44.7 | M9: 0 | N9: 15 | O9: 0.7 | P9: 0 | Q9: =IF($A9="","",IFERROR(MATCH($C9,'합격 기준 수치표'!$B$6:$B$13,0),0)) -> 2 | R9: =IF($A9="","",IF(AND(E9>='합격 기준 수치표'!$D$17,F9>='합격 기준 수치표'!$D$18,F9<='합격 기준 수치표'!$D$19,G9>='합격 기준 수치표'!$D$20,G9<='합격 기준 수치표'!$D$21,P9<='합격 기준 수치표'!$D$23,OR(H9<='합격 기준 수치표'!$D$24,O9="",O9<='합격 기준 수치표'!$D$22)),"OK","X")) -> OK | S9: =IF($A9="","",IF($Q9=0,"?",IF(AND(INDEX('합격 기준 수치표'!$D$6:$D$13,$Q9)="",INDEX('합격 기준 수치표'!$E$6:$E$13,$Q9)=""),"-",IF(H9="","N/A",IF(OR(AND(INDEX('합격 기준 수치표'!$D$6:$D$13,$Q9)<>"",H9<INDEX('합격 기준 수치표'!$D$6:$D$13,$Q9)),AND(INDEX('합격 기준 수치표'!$E$6:$E$13,$Q9)<>"",H9>INDEX('합격 기준 수치표'!$E$6:$E$13,$Q9))),"X","OK"))))) -> OK | T9: =IF($A9="","",IF($Q9=0,"?",IF(AND(INDEX('합격 기준 수치표'!$F$6:$F$13,$Q9)="",INDEX('합격 기준 수치표'!$G$6:$G$13,$Q9)=""),"-",IF(I9="","N/A",IF(OR(AND(INDEX('합격 기준 수치표'!$F$6:$F$13,$Q9)<>"",I9<INDEX('합격 기준 수치표'!$F$6:$F$13,$Q9)),AND(INDEX('합격 기준 수치표'!$G$6:$G$13,$Q9)<>"",I9>INDEX('합격 기준 수치표'!$G$6:$G$13,$Q9))),"X","OK"))))) -> OK | U9: =IF($A9="","",IF($Q9=0,"?",IF(AND(INDEX('합격 기준 수치표'!$H$6:$H$13,$Q9)="",INDEX('합격 기준 수치표'!$I$6:$I$13,$Q9)=""),"-",IF(J9="","N/A",IF(OR(AND(INDEX('합격 기준 수치표'!$H$6:$H$13,$Q9)<>"",J9<INDEX('합격 기준 수치표'!$H$6:$H$13,$Q9)),AND(INDEX('합격 기준 수치표'!$I$6:$I$13,$Q9)<>"",J9>INDEX('합격 기준 수치표'!$I$6:$I$13,$Q9))),"X","OK"))))) -> - | V9: =IF($A9="","",IF($Q9=0,"?",IF(AND(INDEX('합격 기준 수치표'!$J$6:$J$13,$Q9)="",INDEX('합격 기준 수치표'!$K$6:$K$13,$Q9)=""),"-",IF(K9="","N/A",IF(OR(AND(INDEX('합격 기준 수치표'!$J$6:$J$13,$Q9)<>"",K9<INDEX('합격 기준 수치표'!$J$6:$J$13,$Q9)),AND(INDEX('합격 기준 수치표'!$K$6:$K$13,$Q9)<>"",K9>INDEX('합격 기준 수치표'!$K$6:$K$13,$Q9))),"X","OK"))))) -> OK | W9: =IF($A9="","",IF($Q9=0,"?",IF(AND(INDEX('합격 기준 수치표'!$L$6:$L$13,$Q9)="",INDEX('합격 기준 수치표'!$M$6:$M$13,$Q9)=""),"-",IF(L9="","N/A",IF(OR(AND(INDEX('합격 기준 수치표'!$L$6:$L$13,$Q9)<>"",L9<INDEX('합격 기준 수치표'!$L$6:$L$13,$Q9)),AND(INDEX('합격 기준 수치표'!$M$6:$M$13,$Q9)<>"",L9>INDEX('합격 기준 수치표'!$M$6:$M$13,$Q9))),"X","OK"))))) -> - | X9: =IF($A9="","",IF($Q9=0,"?",IF(AND(INDEX('합격 기준 수치표'!$N$6:$N$13,$Q9)="",INDEX('합격 기준 수치표'!$O$6:$O$13,$Q9)=""),"-",IF(M9="","N/A",IF(OR(AND(INDEX('합격 기준 수치표'!$N$6:$N$13,$Q9)<>"",M9<INDEX('합격 기준 수치표'!$N$6:$N$13,$Q9)),AND(INDEX('합격 기준 수치표'!$O$6:$O$13,$Q9)<>"",M9>INDEX('합격 기준 수치표'!$O$6:$O$13,$Q9))),"X","OK"))))) -> - | Y9: =IF($A9="","",IF($Q9=0,"?",IF(AND(INDEX('합격 기준 수치표'!$P$6:$P$13,$Q9)="",INDEX('합격 기준 수치표'!$Q$6:$Q$13,$Q9)=""),"-",IF(N9="","N/A",IF(OR(AND(INDEX('합격 기준 수치표'!$P$6:$P$13,$Q9)<>"",N9<INDEX('합격 기준 수치표'!$P$6:$P$13,$Q9)),AND(INDEX('합격 기준 수치표'!$Q$6:$Q$13,$Q9)<>"",N9>INDEX('합격 기준 수치표'!$Q$6:$Q$13,$Q9))),"X","OK"))))) -> OK | Z9: =IF($A9="","",COUNTIF($S9:$Y9,"X")+IF($R9="X",1,0)) -> 0 | AA9: =IF($A9="","",IF($Q9=0,"자세명 확인",IF($Z9=0,"PASS","FAIL"))) -> PASS
A10: aro_turtle_neck_1.csv | B10: aro | C10: turtle_neck | D10: 1 | E10: 1245 | F10: 20 | G10: 62.3 | H10: 11724 | I10: 236 | J10: 51.6 | K10: 52.4 | L10: 59.2 | M10: 0 | N10: 2 | O10: 17.6 | P10: 0 | Q10: =IF($A10="","",IFERROR(MATCH($C10,'합격 기준 수치표'!$B$6:$B$13,0),0)) -> 8 | R10: =IF($A10="","",IF(AND(E10>='합격 기준 수치표'!$D$17,F10>='합격 기준 수치표'!$D$18,F10<='합격 기준 수치표'!$D$19,G10>='합격 기준 수치표'!$D$20,G10<='합격 기준 수치표'!$D$21,P10<='합격 기준 수치표'!$D$23,OR(H10<='합격 기준 수치표'!$D$24,O10="",O10<='합격 기준 수치표'!$D$22)),"OK","X")) -> X | S10: =IF($A10="","",IF($Q10=0,"?",IF(AND(INDEX('합격 기준 수치표'!$D$6:$D$13,$Q10)="",INDEX('합격 기준 수치표'!$E$6:$E$13,$Q10)=""),"-",IF(H10="","N/A",IF(OR(AND(INDEX('합격 기준 수치표'!$D$6:$D$13,$Q10)<>"",H10<INDEX('합격 기준 수치표'!$D$6:$D$13,$Q10)),AND(INDEX('합격 기준 수치표'!$E$6:$E$13,$Q10)<>"",H10>INDEX('합격 기준 수치표'!$E$6:$E$13,$Q10))),"X","OK"))))) -> OK | T10: =IF($A10="","",IF($Q10=0,"?",IF(AND(INDEX('합격 기준 수치표'!$F$6:$F$13,$Q10)="",INDEX('합격 기준 수치표'!$G$6:$G$13,$Q10)=""),"-",IF(I10="","N/A",IF(OR(AND(INDEX('합격 기준 수치표'!$F$6:$F$13,$Q10)<>"",I10<INDEX('합격 기준 수치표'!$F$6:$F$13,$Q10)),AND(INDEX('합격 기준 수치표'!$G$6:$G$13,$Q10)<>"",I10>INDEX('합격 기준 수치표'!$G$6:$G$13,$Q10))),"X","OK"))))) -> X | U10: =IF($A10="","",IF($Q10=0,"?",IF(AND(INDEX('합격 기준 수치표'!$H$6:$H$13,$Q10)="",INDEX('합격 기준 수치표'!$I$6:$I$13,$Q10)=""),"-",IF(J10="","N/A",IF(OR(AND(INDEX('합격 기준 수치표'!$H$6:$H$13,$Q10)<>"",J10<INDEX('합격 기준 수치표'!$H$6:$H$13,$Q10)),AND(INDEX('합격 기준 수치표'!$I$6:$I$13,$Q10)<>"",J10>INDEX('합격 기준 수치표'!$I$6:$I$13,$Q10))),"X","OK"))))) -> - | V10: =IF($A10="","",IF($Q10=0,"?",IF(AND(INDEX('합격 기준 수치표'!$J$6:$J$13,$Q10)="",INDEX('합격 기준 수치표'!$K$6:$K$13,$Q10)=""),"-",IF(K10="","N/A",IF(OR(AND(INDEX('합격 기준 수치표'!$J$6:$J$13,$Q10)<>"",K10<INDEX('합격 기준 수치표'!$J$6:$J$13,$Q10)),AND(INDEX('합격 기준 수치표'!$K$6:$K$13,$Q10)<>"",K10>INDEX('합격 기준 수치표'!$K$6:$K$13,$Q10))),"X","OK"))))) -> OK | W10: =IF($A10="","",IF($Q10=0,"?",IF(AND(INDEX('합격 기준 수치표'!$L$6:$L$13,$Q10)="",INDEX('합격 기준 수치표'!$M$6:$M$13,$Q10)=""),"-",IF(L10="","N/A",IF(OR(AND(INDEX('합격 기준 수치표'!$L$6:$L$13,$Q10)<>"",L10<INDEX('합격 기준 수치표'!$L$6:$L$13,$Q10)),AND(INDEX('합격 기준 수치표'!$M$6:$M$13,$Q10)<>"",L10>INDEX('합격 기준 수치표'!$M$6:$M$13,$Q10))),"X","OK"))))) -> - | X10: =IF($A10="","",IF($Q10=0,"?",IF(AND(INDEX('합격 기준 수치표'!$N$6:$N$13,$Q10)="",INDEX('합격 기준 수치표'!$O$6:$O$13,$Q10)=""),"-",IF(M10="","N/A",IF(OR(AND(INDEX('합격 기준 수치표'!$N$6:$N$13,$Q10)<>"",M10<INDEX('합격 기준 수치표'!$N$6:$N$13,$Q10)),AND(INDEX('합격 기준 수치표'!$O$6:$O$13,$Q10)<>"",M10>INDEX('합격 기준 수치표'!$O$6:$O$13,$Q10))),"X","OK"))))) -> OK | Y10: =IF($A10="","",IF($Q10=0,"?",IF(AND(INDEX('합격 기준 수치표'!$P$6:$P$13,$Q10)="",INDEX('합격 기준 수치표'!$Q$6:$Q$13,$Q10)=""),"-",IF(N10="","N/A",IF(OR(AND(INDEX('합격 기준 수치표'!$P$6:$P$13,$Q10)<>"",N10<INDEX('합격 기준 수치표'!$P$6:$P$13,$Q10)),AND(INDEX('합격 기준 수치표'!$Q$6:$Q$13,$Q10)<>"",N10>INDEX('합격 기준 수치표'!$Q$6:$Q$13,$Q10))),"X","OK"))))) -> X | Z10: =IF($A10="","",COUNTIF($S10:$Y10,"X")+IF($R10="X",1,0)) -> 3 | AA10: =IF($A10="","",IF($Q10=0,"자세명 확인",IF($Z10=0,"PASS","FAIL"))) -> FAIL
A11: dahye_cross_leg_left_3.csv | B11: dahye | C11: cross_leg_left | D11: 3 | E11: 1244 | F11: 20 | G11: 62.2 | H11: 12104 | I11: 2820 | J11: 47.3 | K11: 66.7 | L11: 44.6 | M11: 36.3 | N11: 14 | O11: 2.3 | P11: 0 | Q11: =IF($A11="","",IFERROR(MATCH($C11,'합격 기준 수치표'!$B$6:$B$13,0),0)) -> 5 | R11: =IF($A11="","",IF(AND(E11>='합격 기준 수치표'!$D$17,F11>='합격 기준 수치표'!$D$18,F11<='합격 기준 수치표'!$D$19,G11>='합격 기준 수치표'!$D$20,G11<='합격 기준 수치표'!$D$21,P11<='합격 기준 수치표'!$D$23,OR(H11<='합격 기준 수치표'!$D$24,O11="",O11<='합격 기준 수치표'!$D$22)),"OK","X")) -> OK | S11: =IF($A11="","",IF($Q11=0,"?",IF(AND(INDEX('합격 기준 수치표'!$D$6:$D$13,$Q11)="",INDEX('합격 기준 수치표'!$E$6:$E$13,$Q11)=""),"-",IF(H11="","N/A",IF(OR(AND(INDEX('합격 기준 수치표'!$D$6:$D$13,$Q11)<>"",H11<INDEX('합격 기준 수치표'!$D$6:$D$13,$Q11)),AND(INDEX('합격 기준 수치표'!$E$6:$E$13,$Q11)<>"",H11>INDEX('합격 기준 수치표'!$E$6:$E$13,$Q11))),"X","OK"))))) -> OK | T11: =IF($A11="","",IF($Q11=0,"?",IF(AND(INDEX('합격 기준 수치표'!$F$6:$F$13,$Q11)="",INDEX('합격 기준 수치표'!$G$6:$G$13,$Q11)=""),"-",IF(I11="","N/A",IF(OR(AND(INDEX('합격 기준 수치표'!$F$6:$F$13,$Q11)<>"",I11<INDEX('합격 기준 수치표'!$F$6:$F$13,$Q11)),AND(INDEX('합격 기준 수치표'!$G$6:$G$13,$Q11)<>"",I11>INDEX('합격 기준 수치표'!$G$6:$G$13,$Q11))),"X","OK"))))) -> OK | U11: =IF($A11="","",IF($Q11=0,"?",IF(AND(INDEX('합격 기준 수치표'!$H$6:$H$13,$Q11)="",INDEX('합격 기준 수치표'!$I$6:$I$13,$Q11)=""),"-",IF(J11="","N/A",IF(OR(AND(INDEX('합격 기준 수치표'!$H$6:$H$13,$Q11)<>"",J11<INDEX('합격 기준 수치표'!$H$6:$H$13,$Q11)),AND(INDEX('합격 기준 수치표'!$I$6:$I$13,$Q11)<>"",J11>INDEX('합격 기준 수치표'!$I$6:$I$13,$Q11))),"X","OK"))))) -> - | V11: =IF($A11="","",IF($Q11=0,"?",IF(AND(INDEX('합격 기준 수치표'!$J$6:$J$13,$Q11)="",INDEX('합격 기준 수치표'!$K$6:$K$13,$Q11)=""),"-",IF(K11="","N/A",IF(OR(AND(INDEX('합격 기준 수치표'!$J$6:$J$13,$Q11)<>"",K11<INDEX('합격 기준 수치표'!$J$6:$J$13,$Q11)),AND(INDEX('합격 기준 수치표'!$K$6:$K$13,$Q11)<>"",K11>INDEX('합격 기준 수치표'!$K$6:$K$13,$Q11))),"X","OK"))))) -> OK | W11: =IF($A11="","",IF($Q11=0,"?",IF(AND(INDEX('합격 기준 수치표'!$L$6:$L$13,$Q11)="",INDEX('합격 기준 수치표'!$M$6:$M$13,$Q11)=""),"-",IF(L11="","N/A",IF(OR(AND(INDEX('합격 기준 수치표'!$L$6:$L$13,$Q11)<>"",L11<INDEX('합격 기준 수치표'!$L$6:$L$13,$Q11)),AND(INDEX('합격 기준 수치표'!$M$6:$M$13,$Q11)<>"",L11>INDEX('합격 기준 수치표'!$M$6:$M$13,$Q11))),"X","OK"))))) -> - | X11: =IF($A11="","",IF($Q11=0,"?",IF(AND(INDEX('합격 기준 수치표'!$N$6:$N$13,$Q11)="",INDEX('합격 기준 수치표'!$O$6:$O$13,$Q11)=""),"-",IF(M11="","N/A",IF(OR(AND(INDEX('합격 기준 수치표'!$N$6:$N$13,$Q11)<>"",M11<INDEX('합격 기준 수치표'!$N$6:$N$13,$Q11)),AND(INDEX('합격 기준 수치표'!$O$6:$O$13,$Q11)<>"",M11>INDEX('합격 기준 수치표'!$O$6:$O$13,$Q11))),"X","OK"))))) -> - | Y11: =IF($A11="","",IF($Q11=0,"?",IF(AND(INDEX('합격 기준 수치표'!$P$6:$P$13,$Q11)="",INDEX('합격 기준 수치표'!$Q$6:$Q$13,$Q11)=""),"-",IF(N11="","N/A",IF(OR(AND(INDEX('합격 기준 수치표'!$P$6:$P$13,$Q11)<>"",N11<INDEX('합격 기준 수치표'!$P$6:$P$13,$Q11)),AND(INDEX('합격 기준 수치표'!$Q$6:$Q$13,$Q11)<>"",N11>INDEX('합격 기준 수치표'!$Q$6:$Q$13,$Q11))),"X","OK"))))) -> OK | Z11: =IF($A11="","",COUNTIF($S11:$Y11,"X")+IF($R11="X",1,0)) -> 0 | AA11: =IF($A11="","",IF($Q11=0,"자세명 확인",IF($Z11=0,"PASS","FAIL"))) -> PASS
A12: dahye_cross_leg_right_1.csv | B12: dahye | C12: cross_leg_right | D12: 1 | E12: 1245 | F12: 20 | G12: 62.3 | H12: 10400 | I12: 1855 | J12: 47.1 | K12: 36.2 | L12: 23.6 | M12: 46.4 | N12: 11 | O12: 3.6 | P12: 0 | Q12: =IF($A12="","",IFERROR(MATCH($C12,'합격 기준 수치표'!$B$6:$B$13,0),0)) -> 4 | R12: =IF($A12="","",IF(AND(E12>='합격 기준 수치표'!$D$17,F12>='합격 기준 수치표'!$D$18,F12<='합격 기준 수치표'!$D$19,G12>='합격 기준 수치표'!$D$20,G12<='합격 기준 수치표'!$D$21,P12<='합격 기준 수치표'!$D$23,OR(H12<='합격 기준 수치표'!$D$24,O12="",O12<='합격 기준 수치표'!$D$22)),"OK","X")) -> OK | S12: =IF($A12="","",IF($Q12=0,"?",IF(AND(INDEX('합격 기준 수치표'!$D$6:$D$13,$Q12)="",INDEX('합격 기준 수치표'!$E$6:$E$13,$Q12)=""),"-",IF(H12="","N/A",IF(OR(AND(INDEX('합격 기준 수치표'!$D$6:$D$13,$Q12)<>"",H12<INDEX('합격 기준 수치표'!$D$6:$D$13,$Q12)),AND(INDEX('합격 기준 수치표'!$E$6:$E$13,$Q12)<>"",H12>INDEX('합격 기준 수치표'!$E$6:$E$13,$Q12))),"X","OK"))))) -> OK | T12: =IF($A12="","",IF($Q12=0,"?",IF(AND(INDEX('합격 기준 수치표'!$F$6:$F$13,$Q12)="",INDEX('합격 기준 수치표'!$G$6:$G$13,$Q12)=""),"-",IF(I12="","N/A",IF(OR(AND(INDEX('합격 기준 수치표'!$F$6:$F$13,$Q12)<>"",I12<INDEX('합격 기준 수치표'!$F$6:$F$13,$Q12)),AND(INDEX('합격 기준 수치표'!$G$6:$G$13,$Q12)<>"",I12>INDEX('합격 기준 수치표'!$G$6:$G$13,$Q12))),"X","OK"))))) -> OK | U12: =IF($A12="","",IF($Q12=0,"?",IF(AND(INDEX('합격 기준 수치표'!$H$6:$H$13,$Q12)="",INDEX('합격 기준 수치표'!$I$6:$I$13,$Q12)=""),"-",IF(J12="","N/A",IF(OR(AND(INDEX('합격 기준 수치표'!$H$6:$H$13,$Q12)<>"",J12<INDEX('합격 기준 수치표'!$H$6:$H$13,$Q12)),AND(INDEX('합격 기준 수치표'!$I$6:$I$13,$Q12)<>"",J12>INDEX('합격 기준 수치표'!$I$6:$I$13,$Q12))),"X","OK"))))) -> - | V12: =IF($A12="","",IF($Q12=0,"?",IF(AND(INDEX('합격 기준 수치표'!$J$6:$J$13,$Q12)="",INDEX('합격 기준 수치표'!$K$6:$K$13,$Q12)=""),"-",IF(K12="","N/A",IF(OR(AND(INDEX('합격 기준 수치표'!$J$6:$J$13,$Q12)<>"",K12<INDEX('합격 기준 수치표'!$J$6:$J$13,$Q12)),AND(INDEX('합격 기준 수치표'!$K$6:$K$13,$Q12)<>"",K12>INDEX('합격 기준 수치표'!$K$6:$K$13,$Q12))),"X","OK"))))) -> OK | W12: =IF($A12="","",IF($Q12=0,"?",IF(AND(INDEX('합격 기준 수치표'!$L$6:$L$13,$Q12)="",INDEX('합격 기준 수치표'!$M$6:$M$13,$Q12)=""),"-",IF(L12="","N/A",IF(OR(AND(INDEX('합격 기준 수치표'!$L$6:$L$13,$Q12)<>"",L12<INDEX('합격 기준 수치표'!$L$6:$L$13,$Q12)),AND(INDEX('합격 기준 수치표'!$M$6:$M$13,$Q12)<>"",L12>INDEX('합격 기준 수치표'!$M$6:$M$13,$Q12))),"X","OK"))))) -> - | X12: =IF($A12="","",IF($Q12=0,"?",IF(AND(INDEX('합격 기준 수치표'!$N$6:$N$13,$Q12)="",INDEX('합격 기준 수치표'!$O$6:$O$13,$Q12)=""),"-",IF(M12="","N/A",IF(OR(AND(INDEX('합격 기준 수치표'!$N$6:$N$13,$Q12)<>"",M12<INDEX('합격 기준 수치표'!$N$6:$N$13,$Q12)),AND(INDEX('합격 기준 수치표'!$O$6:$O$13,$Q12)<>"",M12>INDEX('합격 기준 수치표'!$O$6:$O$13,$Q12))),"X","OK"))))) -> - | Y12: =IF($A12="","",IF($Q12=0,"?",IF(AND(INDEX('합격 기준 수치표'!$P$6:$P$13,$Q12)="",INDEX('합격 기준 수치표'!$Q$6:$Q$13,$Q12)=""),"-",IF(N12="","N/A",IF(OR(AND(INDEX('합격 기준 수치표'!$P$6:$P$13,$Q12)<>"",N12<INDEX('합격 기준 수치표'!$P$6:$P$13,$Q12)),AND(INDEX('합격 기준 수치표'!$Q$6:$Q$13,$Q12)<>"",N12>INDEX('합격 기준 수치표'!$Q$6:$Q$13,$Q12))),"X","OK"))))) -> OK | Z12: =IF($A12="","",COUNTIF($S12:$Y12,"X")+IF($R12="X",1,0)) -> 0 | AA12: =IF($A12="","",IF($Q12=0,"자세명 확인",IF($Z12=0,"PASS","FAIL"))) -> PASS
